[01/31/2025 12:22:07 AM] [DEBUG] [genailab.infra.persist.repo.object.rao.RAO] [rao] [__init__] : RAO created at workspace/test/datasets/ral/
[01/31/2025 12:22:07 AM] [DEBUG] [genailab.infra.persist.repo.object.dao.DAO] [dao] [__init__] : DAO created at workspace/test/datasets/dal/
[01/31/2025 12:22:09 AM] [DEBUG] [asyncio] [selector_events] [__init__] : Using selector: EpollSelector
[01/31/2025 12:22:11 AM] [DEBUG] [genailab.flow.base.stage.TQAStage] [stage] [run] : Inside TQAStage: run
[01/31/2025 12:22:11 AM] [DEBUG] [genailab.flow.base.stage.TQAStage] [stage] [_dataset_exists] : Inside TQAStage: _dataset_exists
[01/31/2025 12:22:11 AM] [DEBUG] [genailab.flow.base.stage.TQAStage] [stage] [_fresh_cache_exists] : Inside TQAStage: _fresh_cache_exists
[01/31/2025 12:22:11 AM] [DEBUG] [genailab.flow.base.stage.TQAStage] [stage] [_get_dataset] : Inside TQAStage: _get_dataset
[01/31/2025 12:22:11 AM] [DEBUG] [genailab.flow.base.stage.TQAStage] [stage] [_dataset_exists] : Inside TQAStage: _dataset_exists
[01/31/2025 12:22:11 AM] [DEBUG] [genailab.flow.base.stage.TQAStage] [stage] [_fresh_cache_exists] : The target dataset cache for Feature Engineering Phase/Text Quality Analysis Stage exists in the repository.
[01/31/2025 12:22:11 AM] [DEBUG] [genailab.flow.base.stage.TQAStage] [stage] [_run] : Inside TQAStage: _run
[01/31/2025 12:22:11 AM] [DEBUG] [genailab.flow.base.stage.TQAStage] [stage] [_remove_dataset] : Inside TQAStage: _remove_dataset
[01/31/2025 12:22:11 AM] [DEBUG] [genailab.infra.persist.repo.file.fao.FAO] [fao] [delete] : Directory feature_tqadask_dataset_review.parquet successfully removed from the repository.
[01/31/2025 12:22:11 AM] [DEBUG] [genailab.infra.persist.repo.dataset.DatasetRepo] [dataset] [remove] : Files for Dataset feature_tqadask_dataset_review removed from repository.
[01/31/2025 12:22:11 AM] [DEBUG] [genailab.infra.persist.repo.object.dao.DAO] [dao] [delete] : Dataset object feature_tqadask_dataset_review removed from object storage.
[01/31/2025 12:22:11 AM] [DEBUG] [genailab.infra.persist.repo.dataset.DatasetRepo] [dataset] [remove] : Dataset feature_tqadask_dataset_review, including its file at workspace/test/datasets/fal/feature/feature_tqadask_dataset_review.parquet has been removed from the repository.
[01/31/2025 12:22:11 AM] [DEBUG] [genailab.flow.base.stage.TQAStage] [stage] [_get_dataset] : Inside TQAStage: _get_dataset
[01/31/2025 12:22:11 AM] [DEBUG] [root] [factory] [get_reader] : Requesting a pandas_parquet reader from the DataFrameIOFactory
[01/31/2025 12:22:11 AM] [DEBUG] [genailab.infra.persist.repo.file.pandas.PandasDataFrameParquetReader] [pandas] [read] : PandasDataFrameParquetReader read from workspace/test/datasets/fal/dataprep/dataprep_clean_dataset_review.parquet
[01/31/2025 12:22:11 AM] [DEBUG] [genailab.asset.dataset.state.DatasetState] [state] [add_event] : Added {'timestamp': datetime.datetime(2025, 1, 31, 0, 22, 11, 440872), 'entity': 'TQAStage', 'event': 'Accessed by TQAStage'} to the event log at 2025-01-31 00:22:11.440875.
[01/31/2025 12:22:11 AM] [DEBUG] [genailab.asset.dataset.state.DatasetState] [state] [access] : Dataset accessed by TQAStage at 2025-01-31 00:22:11.440863
[01/31/2025 12:22:11 AM] [DEBUG] [genailab.flow.base.stage.TQAStage] [stage] [_validate_dataframe_type] : Inside TQAStage: _validate_dataframe_type
[01/31/2025 12:22:11 AM] [DEBUG] [genailab.flow.feature.tqa.task.TQADaskTask] [task] [run] : Inside TQADaskTask: run
[01/31/2025 12:22:11 AM] [DEBUG] [genailab.flow.feature.tqa.task.TQADaskTask] [task] [run] : Shape of dataset: (50, 11)
[01/31/2025 12:22:12 AM] [DEBUG] [genailab.flow.feature.tqa.task.TQADaskTask] [task] [run] : Processing in batches...
[01/31/2025 12:22:14 AM] [DEBUG] [genailab.flow.feature.tqa.task.TQADaskTask] [task] [run] : Starting computation in the background with results of type <class 'dask.dataframe.dask_expr._collection.DataFrame'>
[01/31/2025 12:22:14 AM] [DEBUG] [genailab.flow.feature.tqa.task.TQADaskTask] [task] [run] : Beginning to materialize results.
[01/31/2025 12:22:15 AM] [DEBUG] [genailab.flow.feature.tqa.task.TQADaskTask] [task] [_process_batch] : Inside TQADaskTask: _process_batch
[01/31/2025 12:22:15 AM] [DEBUG] [genailab.flow.feature.tqa.task.TQADaskTask] [task] [_process_batch] : Inside TQADaskTask: _process_batch
[01/31/2025 12:22:15 AM] [DEBUG] [genailab.flow.feature.tqa.task.TQADaskTask] [task] [_process_batch] : Inside TQADaskTask: _process_batch
[01/31/2025 12:22:15 AM] [DEBUG] [genailab.flow.feature.tqa.task.TQADaskTask] [task] [_process_batch] : Inside TQADaskTask: _process_batch
[01/31/2025 12:22:15 AM] [DEBUG] [genailab.flow.feature.tqa.task.TQADaskTask] [task] [_process_batch] : Inside TQADaskTask: _process_batch
[01/31/2025 12:22:15 AM] [DEBUG] [genailab.flow.feature.tqa.task.TQADaskTask] [task] [_process_batch] : Inside TQADaskTask: _process_batch
[01/31/2025 12:22:15 AM] [DEBUG] [genailab.flow.feature.tqa.task.TQADaskTask] [task] [_process_batch] : Inside TQADaskTask: _process_batch
[01/31/2025 12:22:15 AM] [DEBUG] [genailab.flow.feature.tqa.task.TQADaskTask] [task] [_process_batch] : Inside TQADaskTask: _process_batch
[01/31/2025 12:22:15 AM] [DEBUG] [genailab.flow.feature.tqa.task.TQADaskTask] [task] [_process_batch] : 
batch_df type: <class 'pandas.core.frame.DataFrame'>
[01/31/2025 12:22:15 AM] [DEBUG] [genailab.flow.feature.tqa.task.TQADaskTask] [task] [_process_batch] : 
batch_df type: <class 'pandas.core.frame.DataFrame'>
[01/31/2025 12:22:15 AM] [DEBUG] [genailab.flow.feature.tqa.task.TQADaskTask] [task] [_process_batch] : 
batch_df type: <class 'pandas.core.frame.DataFrame'>
[01/31/2025 12:22:15 AM] [DEBUG] [genailab.flow.feature.tqa.task.TQADaskTask] [task] [_process_batch] : 
batch_df type: <class 'pandas.core.frame.DataFrame'>
[01/31/2025 12:22:15 AM] [DEBUG] [genailab.flow.feature.tqa.task.TQADaskTask] [task] [_process_batch] : 
batch_df type: <class 'pandas.core.frame.DataFrame'>
[01/31/2025 12:22:15 AM] [DEBUG] [genailab.flow.feature.tqa.task.TQADaskTask] [task] [_process_batch] : 
batch_df type: <class 'pandas.core.frame.DataFrame'>
[01/31/2025 12:22:15 AM] [DEBUG] [genailab.flow.feature.tqa.task.TQADaskTask] [task] [_process_batch] : 
batch_df type: <class 'pandas.core.frame.DataFrame'>
[01/31/2025 12:22:15 AM] [DEBUG] [genailab.flow.feature.tqa.task.TQADaskTask] [task] [_process_batch] : 
function_words type: <class 'set'>
[01/31/2025 12:22:15 AM] [DEBUG] [genailab.flow.feature.tqa.task.TQADaskTask] [task] [_process_batch] : 
function_words type: <class 'set'>
[01/31/2025 12:22:15 AM] [DEBUG] [genailab.flow.feature.tqa.task.TQADaskTask] [task] [_process_batch] : 
function_words type: <class 'set'>
[01/31/2025 12:22:15 AM] [DEBUG] [genailab.flow.feature.tqa.task.TQADaskTask] [task] [_process_batch] : 
function_words type: <class 'set'>
[01/31/2025 12:22:15 AM] [DEBUG] [genailab.flow.feature.tqa.task.TQADaskTask] [task] [_process_batch] : 
function_words type: <class 'set'>
[01/31/2025 12:22:15 AM] [DEBUG] [genailab.flow.feature.tqa.task.TQADaskTask] [task] [_process_batch] : 
function_words type: <class 'set'>
[01/31/2025 12:22:15 AM] [DEBUG] [genailab.flow.feature.tqa.task.TQADaskTask] [task] [_process_batch] : 
function_words type: <class 'set'>
[01/31/2025 12:22:15 AM] [DEBUG] [genailab.flow.feature.tqa.task.TQADaskTask] [task] [_process_batch] : 
batch_df type: <class 'pandas.core.frame.DataFrame'>
[01/31/2025 12:22:15 AM] [DEBUG] [genailab.flow.feature.tqa.task.TQADaskTask] [task] [_process_batch] : 
nlp type: <class 'spacy.lang.en.English'>
[01/31/2025 12:22:15 AM] [DEBUG] [genailab.flow.feature.tqa.task.TQADaskTask] [task] [_process_batch] : 
nlp type: <class 'spacy.lang.en.English'>
[01/31/2025 12:22:15 AM] [DEBUG] [genailab.flow.feature.tqa.task.TQADaskTask] [task] [_process_batch] : 
nlp type: <class 'spacy.lang.en.English'>
[01/31/2025 12:22:15 AM] [DEBUG] [genailab.flow.feature.tqa.task.TQADaskTask] [task] [_process_batch] : 
nlp type: <class 'spacy.lang.en.English'>
[01/31/2025 12:22:15 AM] [DEBUG] [genailab.flow.feature.tqa.task.TQADaskTask] [task] [_process_batch] : 
nlp type: <class 'spacy.lang.en.English'>
[01/31/2025 12:22:15 AM] [DEBUG] [genailab.flow.feature.tqa.task.TQADaskTask] [task] [_process_batch] : 
nlp type: <class 'spacy.lang.en.English'>
[01/31/2025 12:22:15 AM] [DEBUG] [genailab.flow.feature.tqa.task.TQADaskTask] [task] [_process_batch] : 
nlp type: <class 'spacy.lang.en.English'>
[01/31/2025 12:22:15 AM] [DEBUG] [genailab.flow.feature.tqa.task.TQADaskTask] [task] [_process_batch] : 
function_words type: <class 'set'>
[01/31/2025 12:22:15 AM] [DEBUG] [genailab.flow.feature.tqa.task.TQADaskTask] [task] [_process_batch] : 
nlp type: <class 'spacy.lang.en.English'>
[01/31/2025 12:22:22 AM] [ERROR] [TQADaskTask.run] [task] [wrapper] : Exception occurred in TQADaskTask called with                id      app_id                        app_name category_id  \
0     10019409512  1380362212    GALATEA: Novels & Audiobooks        6018   
1     10027124164  1380362212    GALATEA: Novels & Audiobooks        6018   
2     10036938913  1076402606             Libby, by OverDrive        6018   
3     10047764706  1076402606             Libby, by OverDrive        6018   
4     10064456025  1535748732    Storyroom - Webnovel & Story        6018   
...           ...         ...                             ...         ...   
4807   9981346816   947984433                  Amazon Fire TV        6002   
4808   9988091917  1480383173  Fonts Art: Keyboard for iPhone        6002   
4809   9989113281  1146562112                          Safari        6002   
4810   9992810487  1178765645                         Xfinity        6002   
4811   9997018400  1538377576     MP3Converter - Video to MP3        6002   

                    author  rating  \
0     c011c66aae3e668b150e       5   
1     5a2741393dd20358b609       5   
2     46117640263dddac9294       5   
3     a0e95f8868233439444d       5   
4     bb43c451a876165c2abf       1   
...                    ...     ...   
4807  b5c847d2460f932f753b       2   
4808  bf241e59ee6b975a6d9f       5   
4809  516f3e88e0694fb1371d       2   
4810  d63b094fc8a4b37c86a7       1   
4811  598688fceb56a840b319       5   

                                                content  vote_sum  vote_count  \
0     i love it but the chapter and waiting hours fo...         0           0   
1     i like the books that i have read so far if th...         0           0   
2     i have read dozens upon dozens of books after ...         0           0   
3     happy with the app i use it primarily for audi...         0           0   
4     im going to be honest the books are really gre...         0           0   
...                                                 ...       ...         ...   
4807                      it takes a while to reconnect         0           0   
4808  this app is the best font app i ever had you c...         0           0   
4809  its a good app i just want to clear my search ...         0           0   
4810  i want a quick and easy way to sign into my email         0           0   
4811            this app works very well for a free app         0           0   

                          date   category  
0    2023-06-10 15:09:00+00:00       Book  
1    2023-06-12 20:14:00+00:00       Book  
2    2023-06-15 17:01:00+00:00       Book  
3    2023-06-18 19:40:00+00:00       Book  
4    2023-06-23 15:23:00+00:00       Book  
...                        ...        ...  
4807 2023-05-30 16:46:17+00:00  Utilities  
4808 2023-06-01 15:19:14+00:00  Utilities  
4809 2023-06-01 21:52:31+00:00  Utilities  
4810 2023-06-02 22:57:58+00:00  Utilities  
4811 2023-06-04 03:57:09+00:00  Utilities  

[4812 rows x 11 columns]
No dispatch for <class 'dask.dataframe.dask_expr._collection.DataFrame'>
Traceback (most recent call last):
  File "/home/john/projects/genailab/genailab/infra/service/logging/task.py", line 56, in wrapper
    result = func(self, *args, **kwargs)
  File "/home/john/projects/genailab/genailab/flow/feature/tqa/task.py", line 350, in run
    results = results.compute()
  File "/home/john/miniconda3/envs/genai/lib/python3.10/site-packages/dask/dataframe/dask_expr/_collection.py", line 489, in compute
    return DaskMethodsMixin.compute(out, **kwargs)
  File "/home/john/miniconda3/envs/genai/lib/python3.10/site-packages/dask/base.py", line 374, in compute
    (result,) = compute(self, traverse=False, **kwargs)
  File "/home/john/miniconda3/envs/genai/lib/python3.10/site-packages/dask/base.py", line 662, in compute
    results = schedule(dsk, keys, **kwargs)
  File "/home/john/miniconda3/envs/genai/lib/python3.10/site-packages/dask/dataframe/dispatch.py", line 67, in concat
    func = concat_dispatch.dispatch(type(dfs[0]))
  File "/home/john/miniconda3/envs/genai/lib/python3.10/site-packages/dask/utils.py", line 765, in dispatch
    raise TypeError(f"No dispatch for {cls}")
TypeError: No dispatch for <class 'dask.dataframe.dask_expr._collection.DataFrame'>
[01/31/2025 12:22:22 AM] [ERROR] [genailab.flow.base.stage.TQAStage] [stage] [_run] : Error in task TQADaskTask: No dispatch for <class 'dask.dataframe.dask_expr._collection.DataFrame'>
[01/31/2025 12:22:22 AM] [ERROR] [Stage.run] [stage] [wrapper] : Exception occurred in Stage.run called with force=True
Error in task TQADaskTask: No dispatch for <class 'dask.dataframe.dask_expr._collection.DataFrame'>
Traceback (most recent call last):
  File "/home/john/projects/genailab/genailab/flow/feature/tqa/stage.py", line 94, in _run
    dataframe = task.run(dataframe)
  File "/home/john/projects/genailab/genailab/infra/service/logging/task.py", line 56, in wrapper
    result = func(self, *args, **kwargs)
  File "/home/john/projects/genailab/genailab/flow/feature/tqa/task.py", line 350, in run
    results = results.compute()
  File "/home/john/miniconda3/envs/genai/lib/python3.10/site-packages/dask/dataframe/dask_expr/_collection.py", line 489, in compute
    return DaskMethodsMixin.compute(out, **kwargs)
  File "/home/john/miniconda3/envs/genai/lib/python3.10/site-packages/dask/base.py", line 374, in compute
    (result,) = compute(self, traverse=False, **kwargs)
  File "/home/john/miniconda3/envs/genai/lib/python3.10/site-packages/dask/base.py", line 662, in compute
    results = schedule(dsk, keys, **kwargs)
  File "/home/john/miniconda3/envs/genai/lib/python3.10/site-packages/dask/dataframe/dispatch.py", line 67, in concat
    func = concat_dispatch.dispatch(type(dfs[0]))
  File "/home/john/miniconda3/envs/genai/lib/python3.10/site-packages/dask/utils.py", line 765, in dispatch
    raise TypeError(f"No dispatch for {cls}")
TypeError: No dispatch for <class 'dask.dataframe.dask_expr._collection.DataFrame'>

During handling of the above exception, another exception occurred:

Traceback (most recent call last):
  File "/home/john/projects/genailab/genailab/infra/service/logging/stage.py", line 58, in wrapper
    result = func(self, *args, **kwargs)
  File "/home/john/projects/genailab/genailab/flow/base/stage.py", line 147, in run
    return self._run()
  File "/home/john/projects/genailab/genailab/flow/feature/tqa/stage.py", line 97, in _run
    raise RuntimeError(f"Error in task {task.__class__.__name__}: {e}")
RuntimeError: Error in task TQADaskTask: No dispatch for <class 'dask.dataframe.dask_expr._collection.DataFrame'>
[01/31/2025 01:46:03 AM] [DEBUG] [genailab.infra.persist.repo.object.rao.RAO] [rao] [__init__] : RAO created at workspace/test/datasets/ral/
[01/31/2025 01:46:03 AM] [DEBUG] [genailab.infra.persist.repo.object.dao.DAO] [dao] [__init__] : DAO created at workspace/test/datasets/dal/
[01/31/2025 01:46:05 AM] [DEBUG] [asyncio] [selector_events] [__init__] : Using selector: EpollSelector
[01/31/2025 01:46:07 AM] [DEBUG] [genailab.flow.base.stage.TQAStage] [stage] [run] : Inside TQAStage: run
[01/31/2025 01:46:07 AM] [DEBUG] [genailab.flow.base.stage.TQAStage] [stage] [_dataset_exists] : Inside TQAStage: _dataset_exists
[01/31/2025 01:46:07 AM] [DEBUG] [genailab.flow.base.stage.TQAStage] [stage] [_fresh_cache_exists] : Inside TQAStage: _fresh_cache_exists
[01/31/2025 01:46:07 AM] [DEBUG] [genailab.flow.base.stage.TQAStage] [stage] [_get_dataset] : Inside TQAStage: _get_dataset
[01/31/2025 01:46:07 AM] [DEBUG] [genailab.flow.base.stage.TQAStage] [stage] [_dataset_exists] : Inside TQAStage: _dataset_exists
[01/31/2025 01:46:07 AM] [DEBUG] [genailab.flow.base.stage.TQAStage] [stage] [_fresh_cache_exists] : The target dataset cache for Feature Engineering Phase/Text Quality Analysis Stage exists in the repository.
[01/31/2025 01:46:07 AM] [DEBUG] [genailab.flow.base.stage.TQAStage] [stage] [_run] : Inside TQAStage: _run
[01/31/2025 01:46:07 AM] [DEBUG] [genailab.flow.base.stage.TQAStage] [stage] [_remove_dataset] : Inside TQAStage: _remove_dataset
[01/31/2025 01:46:07 AM] [DEBUG] [genailab.infra.persist.repo.file.fao.FAO] [fao] [delete] : Directory feature_tqadask_dataset_review.parquet successfully removed from the repository.
[01/31/2025 01:46:07 AM] [DEBUG] [genailab.infra.persist.repo.dataset.DatasetRepo] [dataset] [remove] : Files for Dataset feature_tqadask_dataset_review removed from repository.
[01/31/2025 01:46:07 AM] [DEBUG] [genailab.infra.persist.repo.object.dao.DAO] [dao] [delete] : Dataset object feature_tqadask_dataset_review removed from object storage.
[01/31/2025 01:46:07 AM] [DEBUG] [genailab.infra.persist.repo.dataset.DatasetRepo] [dataset] [remove] : Dataset feature_tqadask_dataset_review, including its file at workspace/test/datasets/fal/feature/feature_tqadask_dataset_review.parquet has been removed from the repository.
[01/31/2025 01:46:07 AM] [DEBUG] [genailab.flow.base.stage.TQAStage] [stage] [_get_dataset] : Inside TQAStage: _get_dataset
[01/31/2025 01:46:07 AM] [DEBUG] [root] [factory] [get_reader] : Requesting a pandas_parquet reader from the DataFrameIOFactory
[01/31/2025 01:46:07 AM] [DEBUG] [genailab.infra.persist.repo.file.pandas.PandasDataFrameParquetReader] [pandas] [read] : PandasDataFrameParquetReader read from workspace/test/datasets/fal/dataprep/dataprep_clean_dataset_review.parquet
[01/31/2025 01:46:07 AM] [DEBUG] [genailab.asset.dataset.state.DatasetState] [state] [add_event] : Added {'timestamp': datetime.datetime(2025, 1, 31, 1, 46, 7, 206400), 'entity': 'TQAStage', 'event': 'Accessed by TQAStage'} to the event log at 2025-01-31 01:46:07.206403.
[01/31/2025 01:46:07 AM] [DEBUG] [genailab.asset.dataset.state.DatasetState] [state] [access] : Dataset accessed by TQAStage at 2025-01-31 01:46:07.206391
[01/31/2025 01:46:07 AM] [DEBUG] [genailab.flow.base.stage.TQAStage] [stage] [_validate_dataframe_type] : Inside TQAStage: _validate_dataframe_type
[01/31/2025 01:46:07 AM] [DEBUG] [genailab.flow.feature.tqa.task.TQADaskTask] [task] [run] : Inside TQADaskTask: run
[01/31/2025 01:46:07 AM] [DEBUG] [genailab.flow.feature.tqa.task.TQADaskTask] [task] [run] : Shape of dataset: (50, 11)
[01/31/2025 01:46:08 AM] [DEBUG] [genailab.flow.feature.tqa.task.TQADaskTask] [task] [run] : Processing row-by-row...
[01/31/2025 01:46:10 AM] [DEBUG] [genailab.flow.feature.tqa.task.TQADaskTask] [task] [run] : Starting computation in the background with results of type <class 'dask.dataframe.dask_expr._collection.DataFrame'>
[01/31/2025 01:46:10 AM] [DEBUG] [genailab.flow.feature.tqa.task.TQADaskTask] [task] [run] : Beginning to materialize results.
[01/31/2025 01:46:16 AM] [DEBUG] [genailab.flow.feature.tqa.task.TQADaskTask] [task] [run] : Converted the dask expression to a <class 'pandas.core.frame.DataFrame'> type.
Profile
None
[01/31/2025 01:46:16 AM] [DEBUG] [genailab.flow.feature.tqa.task.TQADaskTask] [task] [run] : Results
              id      app_id                        app_name category_id                author  rating                                                                                                                                                                                                                                                                                                                                                                                                                                                                                                                                                                                                                                                                                                                                                                                                                                                                                                                                                                   content  vote_sum  vote_count                      date           category  noun_count  verb_count  adjective_count  adverb_count  aspect_verb_pairs  noun_phrases  verb_phrases  adverbial_phrases  review_length
132   9752374388  1076402606             Libby, by OverDrive        6018  2234540f27ba9235df9f       1                                                                                                                                                                                                                                                                                                                                                                                                                                                                                                                                                        this is the poorest excuse for a program ive ever seen nor has my son ever seen anything so badly presented and he is a computer expert at several colleges and keep them moving along i liked overdrive simple easy to understand simple to use worked every time the libby i have certainly does not it is just a big fatheadache i know a number of librarians summon my family even and they all agree with me         1           1 2023-03-26 02:10:00+00:00               Book    2.484907    2.639057         2.079442      2.197225           1.386294      2.302585      2.564949           0.693147       4.356709
138   9889678035  1500217654                      AnyStories        6018  097978f165ea70ccc7c4       1                                                                                                                                                                                                                                                                                                                                                                                                                                          i understand the concept and idea behind anystories but to find out it will be or more to read a complete book if you purchase the coins necessary to finish it thats ridiculous then to read a book with chapters earning coins by a daily check in because each chapter is a fraction of a regular book chapter length it will take you months its not an app for readers its just a gimmick that unfortunately new authors are using its a shame and i hope the authors are getting paid by each chapter you have to purchase         0           0 2023-05-03 21:57:00+00:00               Book    3.135494    2.708050         2.079442      1.609438           2.197225      2.833213      2.708050           0.000000       4.595120
455   9709603360  1386412985               WhatsApp Business        6000  a53c8cbb29f5dc2e960e       1                                                                                                                                                                                                                                                                                                                                                                                                                                                                                                                                                                                                                                                                                                                                                                                                                                                                                     its accessing the camera even after a call its going off only when i restart my phone         0           0 2023-03-13 16:22:00+00:00           Business    1.386294    1.386294         0.000000      1.098612           1.098612      1.386294      1.386294           0.000000       2.890372
470   9868809061  1612290431               QR Code: Reader ·        6000  2468a4510e5d8295877a       1                                                                                                                                                                                                                                                                                                                                                                                                                                                                                                                                                                                                                                                                                                                                    free for day trial and then its not clear how to unsubscribe from the app store select your profile little blue person icon then subscriptions and you can unsubscribe from there you can also use a link in apples confirmation email         0           0 2023-04-28 03:46:00+00:00           Business    2.564949    1.609438         1.609438      1.609438           1.098612      2.079442      1.609438           0.000000       3.737670
475   9926919342   906377559                     Zoho Social        6000  a6cff5af1d5a4ffa6047       5                                                                                                                                                                                                                                                                                                                                                                                                                                                                                                                                                                                                                                                                                                                                              ive been a loyal zoho customer for over a decade recently weve switched from hootsuite to zoho social and the result is excellent user experience price and support are incomparable great social media tool keep it up zoho         0           0 2023-05-14 18:08:00+00:00           Business    2.484907    1.098612         1.791759      0.693147           0.693147      2.079442      1.098612           0.000000       3.663562
524   7333834448  1309822135          Procare: Childcare App        6017  8af8db329ffc43271908       4                                                                                                                                                                                                                                                                                                                                                                                                                                                                                                                                                                                                                                                                                                                                                                                                                                                                                                                     looking forward to learning to fully navigate the app         0           0 2021-05-13 14:29:56+00:00          Education    0.693147    1.386294         0.000000      1.098612           0.693147      0.693147      1.386294           0.000000       2.302585
540   7712924248   546473125  Quizlet: Learn with Flashcards        6017  cb45e8ab4297fec635f0       5                                                                                                                                                                                                                                                                                                                                                                                                                                                                                                                                                                                                                                                                                                                                                                                                                                                 really great app helps me study for all my classes and it also is better than writing it down on glass cards savethetrees         0           0 2021-08-20 03:11:33+00:00          Education    1.791759    1.386294         1.098612      1.098612           0.693147      1.609438      1.386294           0.000000       3.178054
631   9084167672   546473125  Quizlet: Learn with Flashcards        6017  47712ad33aa650e47c28       2                                                                                                                                                                                                                                                                                                                                                                                                                                                                                                                                                                                                                                                                                                                                                                                                                                                           it used to be so good but now anytime you want to study you only get a couple rounds of learn and test for free         0           0 2022-09-14 14:32:19+00:00          Education    1.609438    1.609438         1.098612      1.609438           0.693147      1.386294      1.609438           0.000000       3.258097
648   9314960850   570060128     Duolingo - Language Lessons        6017  0e5ffdf73fd012402517       1                                                                                                                                                                                                                                                                                                                                                                                                                                                                                                                                                                                                                                                                                                                                                             please duo release my wife and let my son out of the gulag and also syop bombing australia once i forgot spanish class and a notificatoin said spanish or vanishplease just release them i will do my spanish         1           1 2022-11-22 00:23:24+00:00          Education    2.197225    2.197225         1.098612      1.098612           1.791759      1.945910      2.079442           0.000000       3.663562
1044  9767634899  6443956656                      The Chosen        6016  4730e1a92ac9066e5550       4                                                                                                                                                                                                                                                                                                                                                                                                                                                                                                                                                                                                                                                                                                                                                                                                                                                                                                  thanks for the app would be great if it integrated with apple tv up next         0           0 2023-03-30 12:01:12+00:00      Entertainment    1.609438    0.693147         0.693147      0.693147           0.000000      1.386294      0.693147           0.000000       2.772589
1180  7191673384   540518599                         Wendy’s        6023  7e029848b73c53a4efd5       3                                                                                                                                                                                                                                                                                                                                                                                                                                                                                                                                                                                                                                                                                                                                                                                                                 why is there not an option for spicy nuggets when i do the option they let me in the store the regular ones are nasty over the spicy ones get it together         0           0 2021-04-06 20:38:53+00:00       Food & Drink    2.079442    1.386294         1.386294      0.693147           0.693147      1.945910      1.386294           0.000000       3.496508
1373  8854821291   457494327       Five Guys Burgers & Fries        6023  80c6cb1dcf747b8e9be8       5                                                                                                                                                                                                                                                                                                                                                                                                                                                                                                                                                                                                                                                                                                                                                                                                                                                                                                                              much better and easier to use and understand         0           0 2022-07-09 00:39:54+00:00       Food & Drink    0.000000    1.098612         0.693147      1.098612           0.000000      0.000000      1.098612           0.693147       2.197225
1477  9830221335  1348507359   Arby's - Fast Food Sandwiches        6023  6a6268516c417170acec       1                                                                                                                                                                                                                                                                                                                                                                                                                                                                                                                                                                                                                                                                                                                                                                                                                                                                                                                                             it didnt work donrust the app         0           0 2023-04-17 02:47:22+00:00       Food & Drink    0.693147    1.098612         0.000000      0.000000           0.693147      0.693147      0.693147           0.000000       1.945910
1685  7279127828   577767592   Smoke Free - Quit Smoking Now        6013  aab46e65ee8b8e1e9676       5                                                                                                                                                                                                                                                                                                                                                                                                                                                                                                                                                                                                                                                                                                                                                                  smoke free since january smoked for years even made it through covid what kept me going was seeing how many cigarettes i havent smoked shocking never had a problem with the app give it a try cant hurt         0           0 2021-04-30 01:17:23+00:00   Health & Fitness    1.945910    2.397895         1.386294      1.098612           1.609438      1.791759      2.197225           0.000000       3.663562
1919  8464609454   330376830       Period Tracker by GP Apps        6013  5e878ee9a6deb44a7d69       5                                                                                                                                                                                                                                                                                                                                                                                                                                                                                                                                                                                                                                                                                                                                                                                          pretty great app i like that its easy to use and quite accurate its awesome for a person like me who simply wants to track their period and enter symptoms i may be experiencing         0           0 2022-03-17 09:59:55+00:00   Health & Fitness    1.945910    1.945910         1.098612      1.386294           1.386294      1.791759      1.945910           0.000000       3.555348
1993  8733318214  1178853875    Yoga Workout-Do Yoga At Home        6013  b30c5866cee18ff51463       5                                                                                                                                                                                                                                                                                                                                                                                                                                                                                                                                                                                                                                                                                                                                                                                                                                                         thank you for taking my yoga from simple to challenging and offering everything in between to meet my daily needs         0           0 2022-06-02 13:00:23+00:00   Health & Fitness    1.098612    1.791759         1.098612      0.000000           1.098612      1.098612      1.791759           0.000000       3.044522
2025  8890993110   545849922  Daily Yoga: Fitness+Meditation        6013  9dfe7bb86bec602ca215       5                                                                                                                                                                                                                                                                                                                                                                                                                                                                                                                                                                                                                                                                                                                                                                                                                                                                                        i used this app for the first time today love it and will continue daily thank you         0           0 2022-07-19 20:23:56+00:00   Health & Fitness    1.386294    1.609438         0.693147      0.693147           0.693147      1.098612      1.609438           0.000000       2.890372
2113  9241509447   445899971    Kaiser Permanente Washington        6013  5173f616c7a4af8dd086       1                                                                                                                                                                                                                                                                                                                                                                                                                                                                                                                                                                                                                                                                              this used to be a good app but suddenly it has started crashing every time i open it on the ipad the iphone version still works i have tried deleting and reinstalling yes after a power cycle and it still crashes no way to contact support for the app so i guess we have to post it here         0           0 2022-10-31 18:48:04+00:00   Health & Fitness    2.397895    2.639057         0.693147      1.791759           1.386294      2.197225      2.564949           0.000000       4.077537
2134  9325258941  1528595748            Finch: Self Care Pet        6013  8fdc64911827b98f0e76       5                                                                                                                                                                                                                                                                                                                                                                                                                                                                                                                                                                                                                                                                                                                                                                                                                                                                                i think finch is a good app for letting hurtful feelings come out and make every day spark         0           0 2022-11-25 00:09:36+00:00   Health & Fitness    1.609438    1.609438         1.386294      0.000000           1.098612      1.609438      1.609438           0.000000       2.944439
2172  9492131121  1642532832               MyBenefits Portal        6013  80ff5bf9b6b319b4c746       3                                                                                                                                                                                                                                                                                                                                                                                                                                                                                                                                                                                                                                                                                                                                                                                                                                                                                                   functionsslowly that is but certainly much better than it was initially         0           0 2023-01-10 13:43:42+00:00   Health & Fitness    0.693147    0.000000         0.693147      1.386294           0.000000      0.693147      0.000000           0.000000       2.484907
2184  9542499669  1261033071                    Aetna Health        6013  8358efd6db8afca6aec1       1                                                                                                                                                                                                                                                                                                                                                                                                                                                                                                                                                                                                                                                                                                                                                                                                                                                               trying to write a message but your message center icon is not coming up nothing to click on to send message         0           0 2023-01-24 15:27:16+00:00   Health & Fitness    1.791759    1.791759         0.000000      0.000000           1.386294      1.386294      1.791759           0.000000       3.091042
2249  9750606293  1454778585        Water tracker Waterllama        6013  4c459eece9c688a07cb5       5                                                                                                                                                                                                                                                                                                                                                                                                                                                                                                                                                                                                                                                                                                                                                                       just downloaded this morning so far its great i love how customizable everything is i wanted a water tracking app with a widget that helped me remember how much ive been drinking and this has one         0           0 2023-03-25 14:52:05+00:00   Health & Fitness    1.609438    2.197225         1.386294      1.386294           1.098612      1.386294      2.197225           0.693147       3.610918
2267  9807272610  1528595748            Finch: Self Care Pet        6013  2b07c27fcb055bd61f05       5                                                                                                                                                                                                                                                                                                                                                                                                                                                                                                                                                                                                                                                                                                                                                                                                                                                                                                                           just absolutely love the motivation it gives me         0           0 2023-04-10 15:22:35+00:00   Health & Fitness    0.693147    1.098612         0.000000      1.098612           0.693147      0.693147      1.098612           0.000000       2.197225
2390  7134973302  1494755014            Amazon Shopper Panel        6012  4099e43c16d662c13d2b       5                                                                                                                                                                                                                                                                                                                                                                                                                                                                                                                                                                                                                                                                                                                                                                                                                                                                                                                                                  i love doing the surveys         0           0 2021-03-23 11:16:04+00:00          Lifestyle    0.693147    1.098612         0.000000      0.000000           0.693147      0.693147      1.098612           0.000000       1.791759
2467  7845662474   881999615   Dolly: Moving & Delivery Help        6012  7a1c3b541f41846c6822       3                                                                                                                                                                                                                                                                                                                                                                                                                                                                                                             ive successfully used dolly to pick up single items purchased from a store etc however i attempted to use dolly for a move and man was that a mistake sets of movers took the job showed up and didnt do the job called customer support and they begged me to give it another try they found me a third set of movers who then cancelled the job long story short the move never got done and my mom had to sleep on her mattress on the floor for the night         0           0 2021-09-26 01:55:12+00:00          Lifestyle    3.091042    2.833213         1.386294      1.945910           2.197225      2.772589      2.833213           0.000000       4.510860
2518  8200866475   630119301   Coffee Meets Bagel Dating App        6012  5349ba37f6f1ba6339a4       1                                                                                                                                                                                                                                                                                                                                                                                                                                                                                                                                                                                                                                                                                                                                                                                  when i found a match i liked the algorithm literally told me to pay more money or wait days for her to see your profile it was at that point i realized i was good and done with the app         0           0 2022-01-03 20:50:27+00:00          Lifestyle    1.945910    2.197225         1.098612      0.693147           1.386294      1.791759      2.197225           0.000000       3.713572
2549  8476956264   351331194    Badoo: Dating. Chat. Friends        6012  ef68ccdf4f3b395cde5e       5                                                                                                                                                                                                                                                                                                                                                                                                                                                                                                                                                                                                                                                                                                                                                                                                                                                                                                                                                               like out of         0           0 2022-03-20 16:51:33+00:00          Lifestyle    0.000000    0.000000         0.000000      0.000000           0.000000      0.000000      0.000000           0.000000       1.386294
3020  7004462408   389801252                       Instagram        6008  860de78e9cb9306b5d91       5                                                                                                                                                                                                                                                                                                                                                                                                                                                                                                                                                                                                                                                                                                                                                                                                                                                                                                                          so im new to instagram but im enjoying it so far         0           0 2021-02-17 08:45:00+00:00      Photo & Video    0.693147    1.098612         0.693147      1.386294           0.000000      0.000000      1.098612           0.693147       2.484907
3064  7647900872   389801252                       Instagram        6008  0950e8964ea2dce81de8       3                                                                                                                                                                                                                                                                                                                                                                                                                                                                                                                                                                                                                                     this new update has made instagram even more difficult to navigate and use so far every update and change that the instagram makers have made has made the app less valuable and unique if this continues i see everything eventually going downhill with the app throughout each update i become even more tempted to delete the app         0           0 2021-08-02 21:42:31+00:00      Photo & Video    2.397895    2.484907         1.609438      2.302585           1.609438      2.079442      2.484907           1.386294       4.060443
3100  8096615681   544007664  YouTube: Watch, Listen, Stream        6008  63e3dfb10e6b64a4486f       1                                                                                                                                                                                                                                                                                                                                                                                                                                                                                                                                                                                                                                                                                                                                                                                                                                                                         no dislike button i think youtube is butthurt about their youtube rewind getting lots of dislikes         3           3 2021-12-05 05:51:37+00:00      Photo & Video    2.079442    1.098612         0.693147      0.000000           1.098612      1.386294      1.098612           0.000000       2.833213
3220  9582109305   544007664  YouTube: Watch, Listen, Stream        6008  6a780896730ca6b354c8       5                                                                                                                                                                                                                                                                                                                                                                                                                                                                                                                                                                                                                                                                                                                                                                                                                                                                                                                                       hello i have youtube and it awesome         0           0 2023-02-04 13:36:21+00:00      Photo & Video    0.693147    0.693147         0.000000      0.693147           0.693147      0.000000      0.693147           0.000000       2.079442
3230  9645153553   544007664  YouTube: Watch, Listen, Stream        6008  b38134c6bd174a33a1e8       1                                                                                                                                                                                                                       do you like receiving unwanted and inappropriate advertisements on top of heavily censored videos then youtube maybe be right for you because not only will it be hard to find good content most of which will be mediocre like a netflix original this platform is only good for those seeking a specific video otherwise it has all the entertaining content muted in the background honestly youtube has went from a platform with fun and engaging content to a political product pushing video game etc advertising platform with nothing to keep you latched on to anyone reading i absolutely hands down recommend facebook instagram or the worlds worst platform tiktok at least with those apps youll be entertained with barely any bots         1           1 2023-02-22 23:51:47+00:00      Photo & Video    3.135494    2.890372         2.639057      2.484907           1.791759      2.995732      2.772589           0.000000       4.804021
3613  8598167184   282935706                           Bible        6006  6df0c90f404fbf6d4081       5                                                                                                                                                                                                                                                                                                                                                                                                                                                                                                i love this app for the simple fact its helped me strengthen my faith and educate me on the ways of the lord i love how every bible version is available right at your fingertips but it doesnt stop there theres videos plans prayers verses everything you can possibly imagine this app has helped me in so many ways and i recommend it to anyone just stepping into their faith or anyone looking to strengthen theirs and build a daily habit of connecting with god         0           0 2022-04-23 15:06:58+00:00          Reference    2.564949    2.833213         1.791759      1.791759           1.791759      2.397895      2.833213           0.000000       4.454347
3765  9626802756   282935706                           Bible        6006  f8c694796350d6594ff9       5                                                                                                                                                                                                                                                                                                                                                                                                                                                                                                                                                                                                                                                          although i deeply love the sound of rustling pages in my paper bible and use it primarily this app has kept me on track with daily reading i have been enjoying the daily verse video and prayer suggestions i find myself thinking of them throughout the day which also keeps me in more contact with our lord         0           0 2023-02-17 14:29:49+00:00          Reference    2.639057    2.197225         1.386294      1.386294           1.609438      2.302585      2.197225           0.000000       4.060443
3798  9776216621   282935706                           Bible        6006  69904843f586e78ad2f5       5                                                                                                                                                                                                                                                                                                                                                                                                                                                                                                                                                                                                                                                                                                                                                                                                                                 the bible app is the best app i ever owned helping me get closer to god when you can read it every day is a great feeling i love this app         0           0 2023-04-01 19:01:54+00:00          Reference    1.791759    1.791759         1.386294      0.693147           0.693147      1.791759      1.791759           0.000000       3.465736
3848  9955761374  1573298413    Amen: Daily Catholic Prayers        6006  3f25faf6d5ff2b06c5a1       5                                                                                                                                                                                                                                                                                                                                                                                                                                                                                                                                                                           my day is sliced into a hailstorm of interruptions obligations and pieces of unfinished tasks all clamoring for immediate attention and resolution is it any wonder why my heart and soul are spent completely hollowed out by the time the first stars appear in the night sky your calming prayers offered to an ever present god soothe and remind me of truths greater than my raggedy life         0           0 2023-05-23 03:05:48+00:00          Reference    2.944439    2.197225         1.945910      1.098612           1.098612      2.708050      2.079442           0.000000       4.219508
3951  7392516310   399355755   TextFree: Private Texting App        6005  4425d0b7bcb634d863c2       5                                                                                                                                                                                                                                                                                                                                                                                                                                                                                                                                                                                                                                                                                                                 this app phone company has been a blessing thru these trying messed up times thanks guys for the outstanding service keep it up im sticking with you for all my phone service needs and will be telling all my contacts who is the best provider thanks b         0           0 2021-05-27 00:56:20+00:00  Social Networking    2.639057    1.791759         1.098612      0.000000           1.098612      2.079442      1.791759           0.000000       3.871201
4029  8226184918  1452906710        Wizz - Expand Your World        6005  2d58b3cd664e8d7acd6b       5                                                                                                                                                                                                                                                                                                                                                                                                                                                                                                                                                                                                                                                                                                                                                                                                                                                                                                                                                  its a good app i like it         0           0 2022-01-10 19:21:42+00:00  Social Networking    0.693147    0.693147         0.693147      0.000000           0.000000      0.693147      0.693147           0.000000       2.079442
4030  8226438887  1040207175          Emoji Me Sticker Maker        6005  a12588546e24594b147f       5                                                                                                                                                                                                                                                                                                                                                                                                                                                                                                                                                                                                                                                                                                                                                                                                                                                                                           they can be created so many different ways really funny sending them out thanks         0           0 2022-01-10 21:11:27+00:00  Social Networking    1.098612    1.098612         1.386294      1.098612           0.693147      0.693147      1.098612           0.000000       2.708050
4075  8527059722  1306783602     PLINK – Team Up, Chat, Play        6005  69a1696d29f25cea89dd       1                                                                                                                                                                                                                                                                                                                                                                                                                                                                                                                                                                                                                                                                                                                                                                                                                                                     dont get this app it need to be taken down because why do i see complaints in and the same thing going on say goodbye         0           0 2022-04-03 13:09:10+00:00  Social Networking    1.609438    1.945910         0.693147      0.000000           1.609438      1.098612      1.945910           0.000000       3.258097
4380  7352231952  1499313977               Fonts for iPhones        6002  e09b5937c4bc0b18be1e       5                                                                                                                                                                                                                                                                                                                                                                                                                                                                                                                                                                                                                                                                                                                                                                                                                                                                                                                                                 easy and helps out at lot         0           0 2021-05-17 19:53:03+00:00          Utilities    0.693147    0.693147         0.000000      0.693147           0.000000      0.000000      0.693147           0.693147       1.945910
4404  7499560136  1489389802    Keyboard Fonts ++ Fancy Text        6002  11a7f9f628f4570c50df       5                                                                                                                                                                                                                                                                                                                                                                                                                                                                                                                                                                                                                                                                                                                                                                                                                                                                                                                                   i love this app all kids of cool emojis         0           0 2021-06-24 05:53:54+00:00          Utilities    1.386294    0.693147         0.693147      0.000000           1.098612      1.386294      0.693147           0.000000       2.302585
4426  7664480485  1143920524  Poke Genie -Remote Raid IV PvP        6002  158256d3a6f83230f91a       4                                                                                                                                                                                                                                                                                                                                                                                                                                                                                                                                                                                                                                                                                                                                                                                                    the only reason i did not give it stars is the interface with the game which is a bit tediuos to maintain with deletions and new catches it is hard to keep it current         0           0 2021-08-07 07:37:29+00:00          Utilities    2.197225    1.386294         1.609438      0.000000           0.693147      2.079442      1.386294           0.000000       3.555348
4442  7771311747  1052879175       Brave Private Web Browser        6002  89a33ce3caeb02595939       5                                                                                                                                                                                                                                                                                                                                                                                                                                                                                                                                                                                                                                                                                                                                                                                                                                                                                                           could you let e a custom search engine in private browsing mode         0           0 2021-09-04 20:02:35+00:00          Utilities    1.609438    1.098612         0.693147      0.000000           0.693147      1.386294      0.693147           0.000000       2.564949
4534  8237116840  1245356545   Record it! :: Screen Recorder        6002  f299542affce8ac9a7a0       3  im not trying to break the law i know you need to let people know youcording them on the phone the same way when you call a business they have an automated disclaimer that states this call may be recorded for quality assurance and training purposes per the wiretap law originally established in california but i believe that if a company truly violates someones rights or breaches their own contract they will remove things from what they record i want an app that allows me to record the true full unaltered video andor phone call conversation for pure transparency and to protect myself and my rights a company can do it if they let you know so an individual person can do it if they let you know laws are put in place to protect peoples rights companies dont have rights please fix this app and dont give me any nonsense about it not being legal because ive already explained why that is gradea usda approved male bovine fecal matter         5           8 2022-01-13 22:00:44+00:00          Utilities    3.737670    3.555348         2.397895      1.609438           2.833213      3.367296      3.526361           0.000000       5.141664
4571  8455994231  1495327014                  Renogy DC Home        6002  45cec77147d626f9655d       5                                                                                                                                                                                                                                                                                                                                                                                                                                                                                                                                                                                                                                                                                                                                                                                                                                  i use this to check the charge level of my battery it works as expected i dont have it hooked up to a controller so i cant speak to that         0           0 2022-03-14 21:25:27+00:00          Utilities    1.609438    2.079442         0.000000      0.000000           0.693147      1.386294      2.079442           0.000000       3.433987
4602  8661835946  1521593987    Smart TV Remote for ThinG TV        6002  130adcd9fa8935918e33       1                                                                                                                                                                                                                                                                                                                                                                                                                                                                                                                                                                                                                                                          this is literally useless unless you pay for the premium version i would be perfectly content to view ads and be able to use the app but thats not an option the app will only allow you to press about buttons before completely shutting down and only offering you the option to upgrade dont waste your time         0           0 2022-05-12 02:33:51+00:00          Utilities    2.302585    2.397895         1.386294      1.791759           1.791759      1.945910      2.397895           0.000000       4.060443
4645  9017487249  1504427213    Fonts Keyboard: Cute Symbols        6002  a74105fcc40e8aff9032       5                                                                                                                                                                                                                                                                                                                                                                                                                                                                                                                                                                                                                                                                                                                                                                                                                                                                                                                                 i love this font app bc it has cute fonts         0           0 2022-08-26 03:19:38+00:00          Utilities    1.098612    1.098612         1.098612      0.000000           1.098612      1.098612      1.098612           0.000000       2.397895
4675  9200454388   905953485      NordVPN: VPN Fast & Secure        6002  6d920aefef8a6d7682e6       2                                                                                                                                                                                                                                                                                                                                                                                                                                                                                                                                                                                                                                                                                                                                                                                                                                                                                                     its aight i guess but it keeps logging me out for mow reason so stars         0           0 2022-10-19 13:47:26+00:00          Utilities    1.609438    1.386294         0.000000      0.000000           0.000000      1.386294      1.386294           0.000000       2.772589
4754  9695040373   763638165           IPVanish: Fastest VPN        6002  8d18ea3e7d415562aa65       3                                                                                                                                                                                                                                                                                                                                                                                                                                                                                                                                                                                                                                                                                                                                                                                                                                                                                   new to this i dont really know how this works to much and its not very self explanatory         0           0 2023-03-09 12:38:20+00:00          Utilities    0.693147    1.098612         1.386294      1.098612           0.000000      0.693147      1.098612           0.000000       2.944439
[01/31/2025 01:46:16 AM] [DEBUG] [genailab.flow.feature.tqa.task.TQADaskTask] [task] [run] : Computation complete.
[01/31/2025 01:46:16 AM] [DEBUG] [TQADaskTask.run] [task] [wrapper] : Task: TQADaskTask
[01/31/2025 01:46:16 AM] [DEBUG] [TQADaskTask.run] [task] [wrapper] : Started: 01:46:07
[01/31/2025 01:46:16 AM] [DEBUG] [TQADaskTask.run] [task] [wrapper] : Completed: 01:46:16
[01/31/2025 01:46:16 AM] [DEBUG] [TQADaskTask.run] [task] [wrapper] : Runtime: 9.29 seconds
[01/31/2025 01:46:16 AM] [DEBUG] [genailab.flow.base.stage.TQAStage] [stage] [_create_dataset] : Inside TQAStage: _create_dataset
[01/31/2025 01:46:16 AM] [DEBUG] [genailab.asset.dataset.builder.DatasetBuilder] [builder] [_build_passport] : 

                        DatasetPassport                         
                        asset_id | feature_tqadask_dataset_review
                           phase | Feature Engineering Phase
                           stage | Text Quality Analysis Stage
                            name | review
                     description | Dataset review created from dataprep_clean_dataset_review in the Feature Engineering Phase - Text Quality Analysis Stage by TQAStage.
                     file_format | parquet
                         creator | TQAStage
                         created | 2025-01-31 01:46:16
                          dftype | pandas


[01/31/2025 01:46:16 AM] [DEBUG] [genailab.asset.dataset.state.DatasetState] [state] [add_event] : Added {'timestamp': datetime.datetime(2025, 1, 31, 1, 46, 16, 584861), 'entity': 'TQAStage', 'event': 'Dataset Created by TQAStage'} to the event log at 2025-01-31 01:46:16.584863.
[01/31/2025 01:46:16 AM] [DEBUG] [genailab.asset.dataset.state.DatasetState] [state] [__post_init__] : TQAStage created dataset at 2025-01-31 01:46:16.584855.
[01/31/2025 01:46:16 AM] [DEBUG] [genailab.asset.dataset.state.DatasetState] [state] [add_event] : Added {'timestamp': datetime.datetime(2025, 1, 31, 1, 46, 16, 585590), 'entity': 'TQAStage', 'event': 'Dataset Published to Repository by TQAStage'} to the event log at 2025-01-31 01:46:16.585592.
[01/31/2025 01:46:16 AM] [DEBUG] [genailab.asset.dataset.state.DatasetState] [state] [publish] : Dataset published by TQAStage at 2025-01-31 01:46:16.585592
[01/31/2025 01:46:16 AM] [DEBUG] [genailab.infra.persist.repo.dataset.DatasetRepo] [dataset] [_get_filepath] : Set Dataset feature_tqadask_dataset_review filepath to workspace/test/datasets/fal/feature/feature_tqadask_dataset_review.parquet
[01/31/2025 01:46:16 AM] [DEBUG] [root] [factory] [get_writer] : Requesting a pandas_parquet writer from the DataFrameIOFactory
[01/31/2025 01:46:16 AM] [DEBUG] [genailab.infra.persist.repo.file.pandas.PandasDataFrameParquetWriter] [pandas] [write] : PandasDataFrameParquetWriter wrote to workspace/test/datasets/fal/feature/feature_tqadask_dataset_review.parquet
[01/31/2025 01:46:16 AM] [DEBUG] [genailab.asset.dataset.state.DatasetState] [state] [add_event] : Added {'timestamp': datetime.datetime(2025, 1, 31, 1, 46, 16, 613847), 'entity': 'TQAStage', 'event': 'Dataset Consumed by TQAStage'} to the event log at 2025-01-31 01:46:16.613851.
[01/31/2025 01:46:16 AM] [DEBUG] [genailab.asset.dataset.state.DatasetState] [state] [consume] : Dataset consumed by TQAStage at 2025-01-31 01:46:16.613851
[01/31/2025 01:46:16 AM] [DEBUG] [Stage.run] [stage] [wrapper] : Stage: Text Quality Analysis Stage
[01/31/2025 01:46:16 AM] [DEBUG] [Stage.run] [stage] [wrapper] : Stage Started: 01:46:07
[01/31/2025 01:46:16 AM] [DEBUG] [Stage.run] [stage] [wrapper] : Stage Completed: 01:46:16
[01/31/2025 01:46:16 AM] [DEBUG] [Stage.run] [stage] [wrapper] : Stage Runtime: 9.57 seconds
[01/31/2025 01:56:49 AM] [DEBUG] [genailab.infra.persist.repo.object.rao.RAO] [rao] [__init__] : RAO created at workspace/test/datasets/ral/
[01/31/2025 01:56:49 AM] [DEBUG] [genailab.infra.persist.repo.object.dao.DAO] [dao] [__init__] : DAO created at workspace/test/datasets/dal/
[01/31/2025 01:56:51 AM] [DEBUG] [asyncio] [selector_events] [__init__] : Using selector: EpollSelector
[01/31/2025 01:56:53 AM] [DEBUG] [genailab.flow.base.stage.TQAStage] [stage] [run] : Inside TQAStage: run
[01/31/2025 01:56:53 AM] [DEBUG] [genailab.flow.base.stage.TQAStage] [stage] [_dataset_exists] : Inside TQAStage: _dataset_exists
[01/31/2025 01:56:53 AM] [DEBUG] [genailab.flow.base.stage.TQAStage] [stage] [_fresh_cache_exists] : Inside TQAStage: _fresh_cache_exists
[01/31/2025 01:56:53 AM] [DEBUG] [genailab.flow.base.stage.TQAStage] [stage] [_get_dataset] : Inside TQAStage: _get_dataset
[01/31/2025 01:56:53 AM] [DEBUG] [genailab.flow.base.stage.TQAStage] [stage] [_dataset_exists] : Inside TQAStage: _dataset_exists
[01/31/2025 01:56:53 AM] [DEBUG] [genailab.flow.base.stage.TQAStage] [stage] [_fresh_cache_exists] : The target dataset cache for Feature Engineering Phase/Text Quality Analysis Stage exists in the repository.
[01/31/2025 01:56:53 AM] [DEBUG] [genailab.flow.base.stage.TQAStage] [stage] [_run] : Inside TQAStage: _run
[01/31/2025 01:56:53 AM] [DEBUG] [genailab.flow.base.stage.TQAStage] [stage] [_remove_dataset] : Inside TQAStage: _remove_dataset
[01/31/2025 01:56:53 AM] [DEBUG] [genailab.infra.persist.repo.file.fao.FAO] [fao] [delete] : Directory feature_tqadask_dataset_review.parquet successfully removed from the repository.
[01/31/2025 01:56:53 AM] [DEBUG] [genailab.infra.persist.repo.dataset.DatasetRepo] [dataset] [remove] : Files for Dataset feature_tqadask_dataset_review removed from repository.
[01/31/2025 01:56:53 AM] [DEBUG] [genailab.infra.persist.repo.object.dao.DAO] [dao] [delete] : Dataset object feature_tqadask_dataset_review removed from object storage.
[01/31/2025 01:56:53 AM] [DEBUG] [genailab.infra.persist.repo.dataset.DatasetRepo] [dataset] [remove] : Dataset feature_tqadask_dataset_review, including its file at workspace/test/datasets/fal/feature/feature_tqadask_dataset_review.parquet has been removed from the repository.
[01/31/2025 01:56:53 AM] [DEBUG] [genailab.flow.base.stage.TQAStage] [stage] [_get_dataset] : Inside TQAStage: _get_dataset
[01/31/2025 01:56:53 AM] [DEBUG] [root] [factory] [get_reader] : Requesting a pandas_parquet reader from the DataFrameIOFactory
[01/31/2025 01:56:53 AM] [DEBUG] [genailab.infra.persist.repo.file.pandas.PandasDataFrameParquetReader] [pandas] [read] : PandasDataFrameParquetReader read from workspace/test/datasets/fal/dataprep/dataprep_clean_dataset_review.parquet
[01/31/2025 01:56:53 AM] [DEBUG] [genailab.asset.dataset.state.DatasetState] [state] [add_event] : Added {'timestamp': datetime.datetime(2025, 1, 31, 1, 56, 53, 465307), 'entity': 'TQAStage', 'event': 'Accessed by TQAStage'} to the event log at 2025-01-31 01:56:53.465310.
[01/31/2025 01:56:53 AM] [DEBUG] [genailab.asset.dataset.state.DatasetState] [state] [access] : Dataset accessed by TQAStage at 2025-01-31 01:56:53.465301
[01/31/2025 01:56:53 AM] [DEBUG] [genailab.flow.base.stage.TQAStage] [stage] [_validate_dataframe_type] : Inside TQAStage: _validate_dataframe_type
[01/31/2025 01:56:53 AM] [DEBUG] [genailab.flow.feature.tqa.task.TQADaskTask] [task] [run] : Inside TQADaskTask: run
[01/31/2025 01:56:53 AM] [DEBUG] [genailab.flow.feature.tqa.task.TQADaskTask] [task] [run] : Shape of dataset: (50, 11)
[01/31/2025 01:56:54 AM] [DEBUG] [genailab.flow.feature.tqa.task.TQADaskTask] [task] [run] : Processing row-by-row...
[01/31/2025 01:56:56 AM] [DEBUG] [genailab.flow.feature.tqa.task.TQADaskTask] [task] [run] : Starting computation in the background with results of type <class 'dask.dataframe.dask_expr._collection.DataFrame'>
[01/31/2025 01:56:56 AM] [DEBUG] [genailab.flow.feature.tqa.task.TQADaskTask] [task] [run] : Beginning to materialize results.
[01/31/2025 01:57:03 AM] [DEBUG] [genailab.flow.feature.tqa.task.TQADaskTask] [task] [run] : Computation complete.
[01/31/2025 01:57:03 AM] [DEBUG] [TQADaskTask.run] [task] [wrapper] : Task: TQADaskTask
[01/31/2025 01:57:03 AM] [DEBUG] [TQADaskTask.run] [task] [wrapper] : Started: 01:56:53
[01/31/2025 01:57:03 AM] [DEBUG] [TQADaskTask.run] [task] [wrapper] : Completed: 01:57:03
[01/31/2025 01:57:03 AM] [DEBUG] [TQADaskTask.run] [task] [wrapper] : Runtime: 9.61 seconds
[01/31/2025 01:57:03 AM] [DEBUG] [genailab.flow.base.stage.TQAStage] [stage] [_create_dataset] : Inside TQAStage: _create_dataset
[01/31/2025 01:57:03 AM] [DEBUG] [genailab.asset.dataset.builder.DatasetBuilder] [builder] [_build_passport] : 

                        DatasetPassport                         
                        asset_id | feature_tqadask_dataset_review
                           phase | Feature Engineering Phase
                           stage | Text Quality Analysis Stage
                            name | review
                     description | Dataset review created from dataprep_clean_dataset_review in the Feature Engineering Phase - Text Quality Analysis Stage by TQAStage.
                     file_format | parquet
                         creator | TQAStage
                         created | 2025-01-31 01:57:03
                          dftype | pandas


[01/31/2025 01:57:03 AM] [DEBUG] [genailab.asset.dataset.state.DatasetState] [state] [add_event] : Added {'timestamp': datetime.datetime(2025, 1, 31, 1, 57, 3, 153072), 'entity': 'TQAStage', 'event': 'Dataset Created by TQAStage'} to the event log at 2025-01-31 01:57:03.153074.
[01/31/2025 01:57:03 AM] [DEBUG] [genailab.asset.dataset.state.DatasetState] [state] [__post_init__] : TQAStage created dataset at 2025-01-31 01:57:03.153065.
[01/31/2025 01:57:03 AM] [DEBUG] [genailab.asset.dataset.state.DatasetState] [state] [add_event] : Added {'timestamp': datetime.datetime(2025, 1, 31, 1, 57, 3, 153445), 'entity': 'TQAStage', 'event': 'Dataset Published to Repository by TQAStage'} to the event log at 2025-01-31 01:57:03.153447.
[01/31/2025 01:57:03 AM] [DEBUG] [genailab.asset.dataset.state.DatasetState] [state] [publish] : Dataset published by TQAStage at 2025-01-31 01:57:03.153447
[01/31/2025 01:57:03 AM] [DEBUG] [genailab.infra.persist.repo.dataset.DatasetRepo] [dataset] [_get_filepath] : Set Dataset feature_tqadask_dataset_review filepath to workspace/test/datasets/fal/feature/feature_tqadask_dataset_review.parquet
[01/31/2025 01:57:03 AM] [DEBUG] [root] [factory] [get_writer] : Requesting a pandas_parquet writer from the DataFrameIOFactory
[01/31/2025 01:57:03 AM] [DEBUG] [genailab.infra.persist.repo.file.pandas.PandasDataFrameParquetWriter] [pandas] [write] : PandasDataFrameParquetWriter wrote to workspace/test/datasets/fal/feature/feature_tqadask_dataset_review.parquet
[01/31/2025 01:57:03 AM] [DEBUG] [genailab.asset.dataset.state.DatasetState] [state] [add_event] : Added {'timestamp': datetime.datetime(2025, 1, 31, 1, 57, 3, 184124), 'entity': 'TQAStage', 'event': 'Dataset Consumed by TQAStage'} to the event log at 2025-01-31 01:57:03.184125.
[01/31/2025 01:57:03 AM] [DEBUG] [genailab.asset.dataset.state.DatasetState] [state] [consume] : Dataset consumed by TQAStage at 2025-01-31 01:57:03.184125
[01/31/2025 01:57:03 AM] [DEBUG] [Stage.run] [stage] [wrapper] : Stage: Text Quality Analysis Stage
[01/31/2025 01:57:03 AM] [DEBUG] [Stage.run] [stage] [wrapper] : Stage Started: 01:56:53
[01/31/2025 01:57:03 AM] [DEBUG] [Stage.run] [stage] [wrapper] : Stage Completed: 01:57:03
[01/31/2025 01:57:03 AM] [DEBUG] [Stage.run] [stage] [wrapper] : Stage Runtime: 9.86 seconds
[01/31/2025 05:21:30 AM] [DEBUG] [genailab.infra.persist.repo.object.rao.RAO] [rao] [__init__] : RAO created at workspace/test/datasets/ral/
[01/31/2025 05:21:30 AM] [DEBUG] [genailab.infra.persist.repo.object.dao.DAO] [dao] [__init__] : DAO created at workspace/test/datasets/dal/
[01/31/2025 05:24:59 AM] [DEBUG] [genailab.infra.persist.repo.object.rao.RAO] [rao] [__init__] : RAO created at workspace/test/datasets/ral/
[01/31/2025 05:24:59 AM] [DEBUG] [genailab.infra.persist.repo.object.dao.DAO] [dao] [__init__] : DAO created at workspace/test/datasets/dal/
[01/31/2025 05:26:02 AM] [DEBUG] [genailab.infra.persist.repo.object.rao.RAO] [rao] [__init__] : RAO created at workspace/test/datasets/ral/
[01/31/2025 05:26:02 AM] [DEBUG] [genailab.infra.persist.repo.object.dao.DAO] [dao] [__init__] : DAO created at workspace/test/datasets/dal/
[01/31/2025 05:26:03 AM] [DEBUG] [genailab.flow.base.stage.TQAStage] [stage] [run] : Inside TQAStage: run
[01/31/2025 05:26:03 AM] [DEBUG] [genailab.flow.base.stage.TQAStage] [stage] [_dataset_exists] : Inside TQAStage: _dataset_exists
[01/31/2025 05:26:03 AM] [DEBUG] [genailab.flow.base.stage.TQAStage] [stage] [_fresh_cache_exists] : Inside TQAStage: _fresh_cache_exists
[01/31/2025 05:26:03 AM] [DEBUG] [genailab.flow.base.stage.TQAStage] [stage] [_get_dataset] : Inside TQAStage: _get_dataset
[01/31/2025 05:26:03 AM] [DEBUG] [genailab.flow.base.stage.TQAStage] [stage] [_dataset_exists] : Inside TQAStage: _dataset_exists
[01/31/2025 05:26:03 AM] [DEBUG] [genailab.flow.base.stage.TQAStage] [stage] [_fresh_cache_exists] : The target dataset cache for Feature Engineering Phase/Text Quality Analysis Stage does not exist in the repository.
[01/31/2025 05:26:03 AM] [DEBUG] [genailab.flow.base.stage.TQAStage] [stage] [_run] : Inside TQAStage: _run
[01/31/2025 05:26:03 AM] [DEBUG] [genailab.flow.base.stage.TQAStage] [stage] [_remove_dataset] : Inside TQAStage: _remove_dataset
[01/31/2025 05:26:03 AM] [DEBUG] [genailab.flow.base.stage.TQAStage] [stage] [_get_dataset] : Inside TQAStage: _get_dataset
[01/31/2025 05:26:03 AM] [DEBUG] [root] [factory] [get_reader] : Requesting a pandas_parquet reader from the DataFrameIOFactory
[01/31/2025 05:26:03 AM] [DEBUG] [genailab.infra.persist.repo.file.pandas.PandasDataFrameParquetReader] [pandas] [read] : PandasDataFrameParquetReader read from workspace/test/datasets/fal/dataprep/dataprep_clean_dataset_review.parquet
[01/31/2025 05:26:03 AM] [DEBUG] [genailab.asset.dataset.state.DatasetState] [state] [add_event] : Added {'timestamp': datetime.datetime(2025, 1, 31, 5, 26, 3, 844965), 'entity': 'TQAStage', 'event': 'Accessed by TQAStage'} to the event log at 2025-01-31 05:26:03.844969.
[01/31/2025 05:26:03 AM] [DEBUG] [genailab.asset.dataset.state.DatasetState] [state] [access] : Dataset accessed by TQAStage at 2025-01-31 05:26:03.844954
[01/31/2025 05:26:03 AM] [DEBUG] [genailab.flow.base.stage.TQAStage] [stage] [_validate_dataframe_type] : Inside TQAStage: _validate_dataframe_type
[01/31/2025 05:26:03 AM] [DEBUG] [asyncio] [selector_events] [__init__] : Using selector: EpollSelector
[01/31/2025 05:26:06 AM] [ERROR] [genailab.flow.base.stage.TQAStage] [stage] [_run] : Error in task TQATask: 'TQAnalystDask' object has no attribute '_dataset_meta'
[01/31/2025 05:26:06 AM] [ERROR] [Stage.run] [stage] [wrapper] : Exception occurred in Stage.run called with force=True
Error in task TQATask: 'TQAnalystDask' object has no attribute '_dataset_meta'
Traceback (most recent call last):
  File "/home/john/projects/genailab/genailab/flow/feature/tqa/stage.py", line 94, in _run
    dataframe = task.run(dataframe)
  File "/home/john/projects/genailab/genailab/flow/feature/tqa/task.py", line 178, in run
    return self._analyst.analyze(data=data)
  File "/home/john/projects/genailab/genailab/flow/feature/tqa/task.py", line 374, in analyze
    meta=self._dataset_meta  # This defines the expected schema for each row's result
AttributeError: 'TQAnalystDask' object has no attribute '_dataset_meta'

During handling of the above exception, another exception occurred:

Traceback (most recent call last):
  File "/home/john/projects/genailab/genailab/infra/service/logging/stage.py", line 58, in wrapper
    result = func(self, *args, **kwargs)
  File "/home/john/projects/genailab/genailab/flow/base/stage.py", line 147, in run
    return self._run()
  File "/home/john/projects/genailab/genailab/flow/feature/tqa/stage.py", line 97, in _run
    raise RuntimeError(f"Error in task {task.__class__.__name__}: {e}")
RuntimeError: Error in task TQATask: 'TQAnalystDask' object has no attribute '_dataset_meta'
[01/31/2025 05:29:10 AM] [DEBUG] [genailab.infra.persist.repo.object.rao.RAO] [rao] [__init__] : RAO created at workspace/test/datasets/ral/
[01/31/2025 05:29:10 AM] [DEBUG] [genailab.infra.persist.repo.object.dao.DAO] [dao] [__init__] : DAO created at workspace/test/datasets/dal/
[01/31/2025 05:29:10 AM] [DEBUG] [genailab.flow.base.stage.TQAStage] [stage] [run] : Inside TQAStage: run
[01/31/2025 05:29:10 AM] [DEBUG] [genailab.flow.base.stage.TQAStage] [stage] [_dataset_exists] : Inside TQAStage: _dataset_exists
[01/31/2025 05:29:10 AM] [DEBUG] [genailab.flow.base.stage.TQAStage] [stage] [_fresh_cache_exists] : Inside TQAStage: _fresh_cache_exists
[01/31/2025 05:29:10 AM] [DEBUG] [genailab.flow.base.stage.TQAStage] [stage] [_get_dataset] : Inside TQAStage: _get_dataset
[01/31/2025 05:29:10 AM] [DEBUG] [genailab.flow.base.stage.TQAStage] [stage] [_dataset_exists] : Inside TQAStage: _dataset_exists
[01/31/2025 05:29:10 AM] [DEBUG] [genailab.flow.base.stage.TQAStage] [stage] [_fresh_cache_exists] : The target dataset cache for Feature Engineering Phase/Text Quality Analysis Stage does not exist in the repository.
[01/31/2025 05:29:10 AM] [DEBUG] [genailab.flow.base.stage.TQAStage] [stage] [_run] : Inside TQAStage: _run
[01/31/2025 05:29:10 AM] [DEBUG] [genailab.flow.base.stage.TQAStage] [stage] [_remove_dataset] : Inside TQAStage: _remove_dataset
[01/31/2025 05:29:10 AM] [DEBUG] [genailab.flow.base.stage.TQAStage] [stage] [_get_dataset] : Inside TQAStage: _get_dataset
[01/31/2025 05:29:10 AM] [DEBUG] [root] [factory] [get_reader] : Requesting a pandas_parquet reader from the DataFrameIOFactory
[01/31/2025 05:29:11 AM] [DEBUG] [genailab.infra.persist.repo.file.pandas.PandasDataFrameParquetReader] [pandas] [read] : PandasDataFrameParquetReader read from workspace/test/datasets/fal/dataprep/dataprep_clean_dataset_review.parquet
[01/31/2025 05:29:11 AM] [DEBUG] [genailab.asset.dataset.state.DatasetState] [state] [add_event] : Added {'timestamp': datetime.datetime(2025, 1, 31, 5, 29, 11, 96537), 'entity': 'TQAStage', 'event': 'Accessed by TQAStage'} to the event log at 2025-01-31 05:29:11.096542.
[01/31/2025 05:29:11 AM] [DEBUG] [genailab.asset.dataset.state.DatasetState] [state] [access] : Dataset accessed by TQAStage at 2025-01-31 05:29:11.096525
[01/31/2025 05:29:11 AM] [DEBUG] [genailab.flow.base.stage.TQAStage] [stage] [_validate_dataframe_type] : Inside TQAStage: _validate_dataframe_type
[01/31/2025 05:29:11 AM] [DEBUG] [asyncio] [selector_events] [__init__] : Using selector: EpollSelector
[01/31/2025 05:29:13 AM] [ERROR] [genailab.flow.base.stage.TQAStage] [stage] [_run] : Error in task TQATask: TQAnalystDask.analyze.<locals>.<lambda>() got an unexpected keyword argument 'meta'
[01/31/2025 05:29:13 AM] [ERROR] [Stage.run] [stage] [wrapper] : Exception occurred in Stage.run called with force=True
Error in task TQATask: TQAnalystDask.analyze.<locals>.<lambda>() got an unexpected keyword argument 'meta'
Traceback (most recent call last):
  File "/home/john/projects/genailab/genailab/flow/feature/tqa/stage.py", line 94, in _run
    dataframe = task.run(dataframe)
  File "/home/john/projects/genailab/genailab/flow/feature/tqa/task.py", line 175, in run
    return self._analyst.analyze(data=data)
  File "/home/john/projects/genailab/genailab/flow/feature/tqa/task.py", line 368, in analyze
    results = data.apply(
  File "/home/john/miniconda3/envs/genai/lib/python3.10/site-packages/pandas/core/frame.py", line 10374, in apply
    return op.apply().__finalize__(self, method="apply")
  File "/home/john/miniconda3/envs/genai/lib/python3.10/site-packages/pandas/core/apply.py", line 916, in apply
    return self.apply_standard()
  File "/home/john/miniconda3/envs/genai/lib/python3.10/site-packages/pandas/core/apply.py", line 1063, in apply_standard
    results, res_index = self.apply_series_generator()
  File "/home/john/miniconda3/envs/genai/lib/python3.10/site-packages/pandas/core/apply.py", line 1081, in apply_series_generator
    results[i] = self.func(v, *self.args, **self.kwargs)
TypeError: TQAnalystDask.analyze.<locals>.<lambda>() got an unexpected keyword argument 'meta'

During handling of the above exception, another exception occurred:

Traceback (most recent call last):
  File "/home/john/projects/genailab/genailab/infra/service/logging/stage.py", line 58, in wrapper
    result = func(self, *args, **kwargs)
  File "/home/john/projects/genailab/genailab/flow/base/stage.py", line 147, in run
    return self._run()
  File "/home/john/projects/genailab/genailab/flow/feature/tqa/stage.py", line 97, in _run
    raise RuntimeError(f"Error in task {task.__class__.__name__}: {e}")
RuntimeError: Error in task TQATask: TQAnalystDask.analyze.<locals>.<lambda>() got an unexpected keyword argument 'meta'
[01/31/2025 06:04:30 AM] [DEBUG] [genailab.infra.persist.repo.object.rao.RAO] [rao] [__init__] : RAO created at workspace/test/datasets/ral/
[01/31/2025 06:04:30 AM] [DEBUG] [genailab.infra.persist.repo.object.dao.DAO] [dao] [__init__] : DAO created at workspace/test/datasets/dal/
[01/31/2025 06:04:31 AM] [DEBUG] [genailab.flow.base.stage.TQAStage] [stage] [run] : Inside TQAStage: run
[01/31/2025 06:04:31 AM] [DEBUG] [genailab.flow.base.stage.TQAStage] [stage] [_dataset_exists] : Inside TQAStage: _dataset_exists
[01/31/2025 06:04:31 AM] [DEBUG] [genailab.flow.base.stage.TQAStage] [stage] [_fresh_cache_exists] : Inside TQAStage: _fresh_cache_exists
[01/31/2025 06:04:31 AM] [DEBUG] [genailab.flow.base.stage.TQAStage] [stage] [_get_dataset] : Inside TQAStage: _get_dataset
[01/31/2025 06:04:31 AM] [DEBUG] [genailab.flow.base.stage.TQAStage] [stage] [_dataset_exists] : Inside TQAStage: _dataset_exists
[01/31/2025 06:04:31 AM] [DEBUG] [genailab.flow.base.stage.TQAStage] [stage] [_fresh_cache_exists] : The target dataset cache for Feature Engineering Phase/Text Quality Analysis Stage does not exist in the repository.
[01/31/2025 06:04:31 AM] [DEBUG] [genailab.flow.base.stage.TQAStage] [stage] [_run] : Inside TQAStage: _run
[01/31/2025 06:04:31 AM] [DEBUG] [genailab.flow.base.stage.TQAStage] [stage] [_remove_dataset] : Inside TQAStage: _remove_dataset
[01/31/2025 06:04:31 AM] [DEBUG] [genailab.flow.base.stage.TQAStage] [stage] [_get_dataset] : Inside TQAStage: _get_dataset
[01/31/2025 06:04:31 AM] [DEBUG] [root] [factory] [get_reader] : Requesting a pandas_parquet reader from the DataFrameIOFactory
[01/31/2025 06:04:31 AM] [DEBUG] [genailab.infra.persist.repo.file.pandas.PandasDataFrameParquetReader] [pandas] [read] : PandasDataFrameParquetReader read from workspace/test/datasets/fal/dataprep/dataprep_clean_dataset_review.parquet
[01/31/2025 06:04:31 AM] [DEBUG] [genailab.asset.dataset.state.DatasetState] [state] [add_event] : Added {'timestamp': datetime.datetime(2025, 1, 31, 6, 4, 31, 614482), 'entity': 'TQAStage', 'event': 'Accessed by TQAStage'} to the event log at 2025-01-31 06:04:31.614485.
[01/31/2025 06:04:31 AM] [DEBUG] [genailab.asset.dataset.state.DatasetState] [state] [access] : Dataset accessed by TQAStage at 2025-01-31 06:04:31.614471
[01/31/2025 06:04:31 AM] [DEBUG] [genailab.flow.base.stage.TQAStage] [stage] [_validate_dataframe_type] : Inside TQAStage: _validate_dataframe_type
[01/31/2025 06:04:31 AM] [DEBUG] [asyncio] [selector_events] [__init__] : Using selector: EpollSelector
[01/31/2025 06:04:34 AM] [ERROR] [genailab.flow.base.stage.TQAStage] [stage] [_run] : Error in task TQATask: TQAnalystDask.analyze.<locals>.<lambda>() got an unexpected keyword argument 'meta'
[01/31/2025 06:04:34 AM] [ERROR] [Stage.run] [stage] [wrapper] : Exception occurred in Stage.run called with force=True
Error in task TQATask: TQAnalystDask.analyze.<locals>.<lambda>() got an unexpected keyword argument 'meta'
Traceback (most recent call last):
  File "/home/john/projects/genailab/genailab/flow/feature/tqa/stage.py", line 94, in _run
    dataframe = task.run(dataframe)
  File "/home/john/projects/genailab/genailab/flow/feature/tqa/task.py", line 144, in run
    return self._analyst.analyze(data=data)
  File "/home/john/projects/genailab/genailab/flow/feature/tqa/task.py", line 364, in analyze
    results = data.apply(
  File "/home/john/miniconda3/envs/genai/lib/python3.10/site-packages/pandas/core/frame.py", line 10374, in apply
    return op.apply().__finalize__(self, method="apply")
  File "/home/john/miniconda3/envs/genai/lib/python3.10/site-packages/pandas/core/apply.py", line 916, in apply
    return self.apply_standard()
  File "/home/john/miniconda3/envs/genai/lib/python3.10/site-packages/pandas/core/apply.py", line 1063, in apply_standard
    results, res_index = self.apply_series_generator()
  File "/home/john/miniconda3/envs/genai/lib/python3.10/site-packages/pandas/core/apply.py", line 1081, in apply_series_generator
    results[i] = self.func(v, *self.args, **self.kwargs)
TypeError: TQAnalystDask.analyze.<locals>.<lambda>() got an unexpected keyword argument 'meta'

During handling of the above exception, another exception occurred:

Traceback (most recent call last):
  File "/home/john/projects/genailab/genailab/infra/service/logging/stage.py", line 58, in wrapper
    result = func(self, *args, **kwargs)
  File "/home/john/projects/genailab/genailab/flow/base/stage.py", line 147, in run
    return self._run()
  File "/home/john/projects/genailab/genailab/flow/feature/tqa/stage.py", line 97, in _run
    raise RuntimeError(f"Error in task {task.__class__.__name__}: {e}")
RuntimeError: Error in task TQATask: TQAnalystDask.analyze.<locals>.<lambda>() got an unexpected keyword argument 'meta'
[01/31/2025 06:11:01 AM] [DEBUG] [genailab.infra.persist.repo.object.rao.RAO] [rao] [__init__] : RAO created at workspace/test/datasets/ral/
[01/31/2025 06:11:01 AM] [DEBUG] [genailab.infra.persist.repo.object.dao.DAO] [dao] [__init__] : DAO created at workspace/test/datasets/dal/
[01/31/2025 06:11:02 AM] [DEBUG] [genailab.flow.base.stage.TQAStage] [stage] [run] : Inside TQAStage: run
[01/31/2025 06:11:02 AM] [DEBUG] [genailab.flow.base.stage.TQAStage] [stage] [_dataset_exists] : Inside TQAStage: _dataset_exists
[01/31/2025 06:11:02 AM] [DEBUG] [genailab.flow.base.stage.TQAStage] [stage] [_fresh_cache_exists] : Inside TQAStage: _fresh_cache_exists
[01/31/2025 06:11:02 AM] [DEBUG] [genailab.flow.base.stage.TQAStage] [stage] [_get_dataset] : Inside TQAStage: _get_dataset
[01/31/2025 06:11:02 AM] [DEBUG] [genailab.flow.base.stage.TQAStage] [stage] [_dataset_exists] : Inside TQAStage: _dataset_exists
[01/31/2025 06:11:02 AM] [DEBUG] [genailab.flow.base.stage.TQAStage] [stage] [_fresh_cache_exists] : The target dataset cache for Feature Engineering Phase/Text Quality Analysis Stage does not exist in the repository.
[01/31/2025 06:11:02 AM] [DEBUG] [genailab.flow.base.stage.TQAStage] [stage] [_run] : Inside TQAStage: _run
[01/31/2025 06:11:02 AM] [DEBUG] [genailab.flow.base.stage.TQAStage] [stage] [_remove_dataset] : Inside TQAStage: _remove_dataset
[01/31/2025 06:11:02 AM] [DEBUG] [genailab.flow.base.stage.TQAStage] [stage] [_get_dataset] : Inside TQAStage: _get_dataset
[01/31/2025 06:11:02 AM] [DEBUG] [root] [factory] [get_reader] : Requesting a pandas_parquet reader from the DataFrameIOFactory
[01/31/2025 06:11:02 AM] [DEBUG] [genailab.infra.persist.repo.file.pandas.PandasDataFrameParquetReader] [pandas] [read] : PandasDataFrameParquetReader read from workspace/test/datasets/fal/dataprep/dataprep_clean_dataset_review.parquet
[01/31/2025 06:11:02 AM] [DEBUG] [genailab.asset.dataset.state.DatasetState] [state] [add_event] : Added {'timestamp': datetime.datetime(2025, 1, 31, 6, 11, 2, 728079), 'entity': 'TQAStage', 'event': 'Accessed by TQAStage'} to the event log at 2025-01-31 06:11:02.728082.
[01/31/2025 06:11:02 AM] [DEBUG] [genailab.asset.dataset.state.DatasetState] [state] [access] : Dataset accessed by TQAStage at 2025-01-31 06:11:02.728072
[01/31/2025 06:11:02 AM] [DEBUG] [genailab.flow.base.stage.TQAStage] [stage] [_validate_dataframe_type] : Inside TQAStage: _validate_dataframe_type
[01/31/2025 06:11:02 AM] [DEBUG] [asyncio] [selector_events] [__init__] : Using selector: EpollSelector
[01/31/2025 06:11:05 AM] [ERROR] [genailab.flow.base.stage.TQAStage] [stage] [_run] : Error in task TQATask: TQAnalystDask.analyze.<locals>.<lambda>() got an unexpected keyword argument 'meta'
[01/31/2025 06:11:05 AM] [ERROR] [Stage.run] [stage] [wrapper] : Exception occurred in Stage.run called with force=True
Error in task TQATask: TQAnalystDask.analyze.<locals>.<lambda>() got an unexpected keyword argument 'meta'
Traceback (most recent call last):
  File "/home/john/projects/genailab/genailab/flow/feature/tqa/stage.py", line 94, in _run
    dataframe = task.run(dataframe)
  File "/home/john/projects/genailab/genailab/flow/feature/tqa/task.py", line 144, in run
    return self._analyst.analyze(data=data)
  File "/home/john/projects/genailab/genailab/flow/feature/tqa/task.py", line 364, in analyze
    results = data.apply(
  File "/home/john/miniconda3/envs/genai/lib/python3.10/site-packages/pandas/core/frame.py", line 10374, in apply
    return op.apply().__finalize__(self, method="apply")
  File "/home/john/miniconda3/envs/genai/lib/python3.10/site-packages/pandas/core/apply.py", line 916, in apply
    return self.apply_standard()
  File "/home/john/miniconda3/envs/genai/lib/python3.10/site-packages/pandas/core/apply.py", line 1063, in apply_standard
    results, res_index = self.apply_series_generator()
  File "/home/john/miniconda3/envs/genai/lib/python3.10/site-packages/pandas/core/apply.py", line 1081, in apply_series_generator
    results[i] = self.func(v, *self.args, **self.kwargs)
TypeError: TQAnalystDask.analyze.<locals>.<lambda>() got an unexpected keyword argument 'meta'

During handling of the above exception, another exception occurred:

Traceback (most recent call last):
  File "/home/john/projects/genailab/genailab/infra/service/logging/stage.py", line 58, in wrapper
    result = func(self, *args, **kwargs)
  File "/home/john/projects/genailab/genailab/flow/base/stage.py", line 147, in run
    return self._run()
  File "/home/john/projects/genailab/genailab/flow/feature/tqa/stage.py", line 97, in _run
    raise RuntimeError(f"Error in task {task.__class__.__name__}: {e}")
RuntimeError: Error in task TQATask: TQAnalystDask.analyze.<locals>.<lambda>() got an unexpected keyword argument 'meta'
[01/31/2025 06:15:53 AM] [DEBUG] [genailab.infra.persist.repo.object.rao.RAO] [rao] [__init__] : RAO created at workspace/test/datasets/ral/
[01/31/2025 06:15:53 AM] [DEBUG] [genailab.infra.persist.repo.object.dao.DAO] [dao] [__init__] : DAO created at workspace/test/datasets/dal/
[01/31/2025 06:15:54 AM] [DEBUG] [genailab.flow.base.stage.TQAStage] [stage] [run] : Inside TQAStage: run
[01/31/2025 06:15:54 AM] [DEBUG] [genailab.flow.base.stage.TQAStage] [stage] [_dataset_exists] : Inside TQAStage: _dataset_exists
[01/31/2025 06:15:54 AM] [DEBUG] [genailab.flow.base.stage.TQAStage] [stage] [_fresh_cache_exists] : Inside TQAStage: _fresh_cache_exists
[01/31/2025 06:15:54 AM] [DEBUG] [genailab.flow.base.stage.TQAStage] [stage] [_get_dataset] : Inside TQAStage: _get_dataset
[01/31/2025 06:15:54 AM] [DEBUG] [genailab.flow.base.stage.TQAStage] [stage] [_dataset_exists] : Inside TQAStage: _dataset_exists
[01/31/2025 06:15:54 AM] [DEBUG] [genailab.flow.base.stage.TQAStage] [stage] [_fresh_cache_exists] : The target dataset cache for Feature Engineering Phase/Text Quality Analysis Stage does not exist in the repository.
[01/31/2025 06:15:54 AM] [DEBUG] [genailab.flow.base.stage.TQAStage] [stage] [_run] : Inside TQAStage: _run
[01/31/2025 06:15:54 AM] [DEBUG] [genailab.flow.base.stage.TQAStage] [stage] [_remove_dataset] : Inside TQAStage: _remove_dataset
[01/31/2025 06:15:54 AM] [DEBUG] [genailab.flow.base.stage.TQAStage] [stage] [_get_dataset] : Inside TQAStage: _get_dataset
[01/31/2025 06:15:54 AM] [DEBUG] [root] [factory] [get_reader] : Requesting a pandas_parquet reader from the DataFrameIOFactory
[01/31/2025 06:15:54 AM] [DEBUG] [genailab.infra.persist.repo.file.pandas.PandasDataFrameParquetReader] [pandas] [read] : PandasDataFrameParquetReader read from workspace/test/datasets/fal/dataprep/dataprep_clean_dataset_review.parquet
[01/31/2025 06:15:54 AM] [DEBUG] [genailab.asset.dataset.state.DatasetState] [state] [add_event] : Added {'timestamp': datetime.datetime(2025, 1, 31, 6, 15, 54, 358997), 'entity': 'TQAStage', 'event': 'Accessed by TQAStage'} to the event log at 2025-01-31 06:15:54.359000.
[01/31/2025 06:15:54 AM] [DEBUG] [genailab.asset.dataset.state.DatasetState] [state] [access] : Dataset accessed by TQAStage at 2025-01-31 06:15:54.358985
[01/31/2025 06:15:54 AM] [DEBUG] [genailab.flow.base.stage.TQAStage] [stage] [_validate_dataframe_type] : Inside TQAStage: _validate_dataframe_type
[01/31/2025 06:15:54 AM] [DEBUG] [asyncio] [selector_events] [__init__] : Using selector: EpollSelector
[01/31/2025 06:15:57 AM] [ERROR] [genailab.flow.base.stage.TQAStage] [stage] [_run] : Error in task TQATask: TQAnalystDask.analyze.<locals>.<lambda>() got an unexpected keyword argument 'meta'
[01/31/2025 06:15:57 AM] [ERROR] [Stage.run] [stage] [wrapper] : Exception occurred in Stage.run called with force=True
Error in task TQATask: TQAnalystDask.analyze.<locals>.<lambda>() got an unexpected keyword argument 'meta'
Traceback (most recent call last):
  File "/home/john/projects/genailab/genailab/flow/feature/tqa/stage.py", line 94, in _run
    dataframe = task.run(dataframe)
  File "/home/john/projects/genailab/genailab/flow/feature/tqa/task.py", line 146, in run
    return self._analyst.analyze(data=data)
  File "/home/john/projects/genailab/genailab/flow/feature/tqa/task.py", line 366, in analyze
    results = data.apply(
  File "/home/john/miniconda3/envs/genai/lib/python3.10/site-packages/pandas/core/frame.py", line 10374, in apply
    return op.apply().__finalize__(self, method="apply")
  File "/home/john/miniconda3/envs/genai/lib/python3.10/site-packages/pandas/core/apply.py", line 916, in apply
    return self.apply_standard()
  File "/home/john/miniconda3/envs/genai/lib/python3.10/site-packages/pandas/core/apply.py", line 1063, in apply_standard
    results, res_index = self.apply_series_generator()
  File "/home/john/miniconda3/envs/genai/lib/python3.10/site-packages/pandas/core/apply.py", line 1081, in apply_series_generator
    results[i] = self.func(v, *self.args, **self.kwargs)
TypeError: TQAnalystDask.analyze.<locals>.<lambda>() got an unexpected keyword argument 'meta'

During handling of the above exception, another exception occurred:

Traceback (most recent call last):
  File "/home/john/projects/genailab/genailab/infra/service/logging/stage.py", line 58, in wrapper
    result = func(self, *args, **kwargs)
  File "/home/john/projects/genailab/genailab/flow/base/stage.py", line 147, in run
    return self._run()
  File "/home/john/projects/genailab/genailab/flow/feature/tqa/stage.py", line 97, in _run
    raise RuntimeError(f"Error in task {task.__class__.__name__}: {e}")
RuntimeError: Error in task TQATask: TQAnalystDask.analyze.<locals>.<lambda>() got an unexpected keyword argument 'meta'
[01/31/2025 06:44:58 AM] [DEBUG] [genailab.infra.persist.repo.object.rao.RAO] [rao] [__init__] : RAO created at workspace/test/datasets/ral/
[01/31/2025 06:44:58 AM] [DEBUG] [genailab.infra.persist.repo.object.dao.DAO] [dao] [__init__] : DAO created at workspace/test/datasets/dal/
[01/31/2025 06:44:59 AM] [DEBUG] [genailab.flow.base.stage.TQAStage] [stage] [run] : Inside TQAStage: run
[01/31/2025 06:44:59 AM] [DEBUG] [genailab.flow.base.stage.TQAStage] [stage] [_dataset_exists] : Inside TQAStage: _dataset_exists
[01/31/2025 06:44:59 AM] [DEBUG] [genailab.flow.base.stage.TQAStage] [stage] [_fresh_cache_exists] : Inside TQAStage: _fresh_cache_exists
[01/31/2025 06:44:59 AM] [DEBUG] [genailab.flow.base.stage.TQAStage] [stage] [_get_dataset] : Inside TQAStage: _get_dataset
[01/31/2025 06:44:59 AM] [DEBUG] [genailab.flow.base.stage.TQAStage] [stage] [_dataset_exists] : Inside TQAStage: _dataset_exists
[01/31/2025 06:44:59 AM] [DEBUG] [genailab.flow.base.stage.TQAStage] [stage] [_fresh_cache_exists] : The target dataset cache for Feature Engineering Phase/Text Quality Analysis Stage does not exist in the repository.
[01/31/2025 06:44:59 AM] [DEBUG] [genailab.flow.base.stage.TQAStage] [stage] [_run] : Inside TQAStage: _run
[01/31/2025 06:44:59 AM] [DEBUG] [genailab.flow.base.stage.TQAStage] [stage] [_remove_dataset] : Inside TQAStage: _remove_dataset
[01/31/2025 06:44:59 AM] [DEBUG] [genailab.flow.base.stage.TQAStage] [stage] [_get_dataset] : Inside TQAStage: _get_dataset
[01/31/2025 06:44:59 AM] [DEBUG] [root] [factory] [get_reader] : Requesting a pandas_parquet reader from the DataFrameIOFactory
[01/31/2025 06:44:59 AM] [DEBUG] [genailab.infra.persist.repo.file.pandas.PandasDataFrameParquetReader] [pandas] [read] : PandasDataFrameParquetReader read from workspace/test/datasets/fal/dataprep/dataprep_clean_dataset_review.parquet
[01/31/2025 06:44:59 AM] [DEBUG] [genailab.asset.dataset.state.DatasetState] [state] [add_event] : Added {'timestamp': datetime.datetime(2025, 1, 31, 6, 44, 59, 324745), 'entity': 'TQAStage', 'event': 'Accessed by TQAStage'} to the event log at 2025-01-31 06:44:59.324751.
[01/31/2025 06:44:59 AM] [DEBUG] [genailab.asset.dataset.state.DatasetState] [state] [access] : Dataset accessed by TQAStage at 2025-01-31 06:44:59.324730
[01/31/2025 06:44:59 AM] [DEBUG] [genailab.flow.base.stage.TQAStage] [stage] [_validate_dataframe_type] : Inside TQAStage: _validate_dataframe_type
[01/31/2025 06:44:59 AM] [DEBUG] [asyncio] [selector_events] [__init__] : Using selector: EpollSelector
[01/31/2025 06:45:02 AM] [ERROR] [genailab.flow.base.stage.TQAStage] [stage] [_run] : Error in task TQATask: DataFrame.apply() got multiple values for argument 'axis'
[01/31/2025 06:45:02 AM] [ERROR] [Stage.run] [stage] [wrapper] : Exception occurred in Stage.run called with force=True
Error in task TQATask: DataFrame.apply() got multiple values for argument 'axis'
Traceback (most recent call last):
  File "/home/john/projects/genailab/genailab/flow/feature/tqa/stage.py", line 94, in _run
    dataframe = task.run(dataframe)
  File "/home/john/projects/genailab/genailab/flow/feature/tqa/task.py", line 146, in run
    return self._analyst.analyze(data=data)
  File "/home/john/projects/genailab/genailab/flow/feature/tqa/task.py", line 366, in analyze
    results = data.apply(self._process_row, function_words, nlp,
TypeError: DataFrame.apply() got multiple values for argument 'axis'

During handling of the above exception, another exception occurred:

Traceback (most recent call last):
  File "/home/john/projects/genailab/genailab/infra/service/logging/stage.py", line 58, in wrapper
    result = func(self, *args, **kwargs)
  File "/home/john/projects/genailab/genailab/flow/base/stage.py", line 147, in run
    return self._run()
  File "/home/john/projects/genailab/genailab/flow/feature/tqa/stage.py", line 97, in _run
    raise RuntimeError(f"Error in task {task.__class__.__name__}: {e}")
RuntimeError: Error in task TQATask: DataFrame.apply() got multiple values for argument 'axis'
[01/31/2025 06:51:30 AM] [DEBUG] [genailab.infra.persist.repo.object.rao.RAO] [rao] [__init__] : RAO created at workspace/test/datasets/ral/
[01/31/2025 06:51:30 AM] [DEBUG] [genailab.infra.persist.repo.object.dao.DAO] [dao] [__init__] : DAO created at workspace/test/datasets/dal/
[01/31/2025 06:51:31 AM] [DEBUG] [genailab.flow.base.stage.TQAStage] [stage] [run] : Inside TQAStage: run
[01/31/2025 06:51:31 AM] [DEBUG] [genailab.flow.base.stage.TQAStage] [stage] [_dataset_exists] : Inside TQAStage: _dataset_exists
[01/31/2025 06:51:31 AM] [DEBUG] [genailab.flow.base.stage.TQAStage] [stage] [_fresh_cache_exists] : Inside TQAStage: _fresh_cache_exists
[01/31/2025 06:51:31 AM] [DEBUG] [genailab.flow.base.stage.TQAStage] [stage] [_get_dataset] : Inside TQAStage: _get_dataset
[01/31/2025 06:51:31 AM] [DEBUG] [genailab.flow.base.stage.TQAStage] [stage] [_dataset_exists] : Inside TQAStage: _dataset_exists
[01/31/2025 06:51:31 AM] [DEBUG] [genailab.flow.base.stage.TQAStage] [stage] [_fresh_cache_exists] : The target dataset cache for Feature Engineering Phase/Text Quality Analysis Stage does not exist in the repository.
[01/31/2025 06:51:31 AM] [DEBUG] [genailab.flow.base.stage.TQAStage] [stage] [_run] : Inside TQAStage: _run
[01/31/2025 06:51:31 AM] [DEBUG] [genailab.flow.base.stage.TQAStage] [stage] [_remove_dataset] : Inside TQAStage: _remove_dataset
[01/31/2025 06:51:31 AM] [DEBUG] [genailab.flow.base.stage.TQAStage] [stage] [_get_dataset] : Inside TQAStage: _get_dataset
[01/31/2025 06:51:31 AM] [DEBUG] [root] [factory] [get_reader] : Requesting a pandas_parquet reader from the DataFrameIOFactory
[01/31/2025 06:51:31 AM] [DEBUG] [genailab.infra.persist.repo.file.pandas.PandasDataFrameParquetReader] [pandas] [read] : PandasDataFrameParquetReader read from workspace/test/datasets/fal/dataprep/dataprep_clean_dataset_review.parquet
[01/31/2025 06:51:31 AM] [DEBUG] [genailab.asset.dataset.state.DatasetState] [state] [add_event] : Added {'timestamp': datetime.datetime(2025, 1, 31, 6, 51, 31, 622615), 'entity': 'TQAStage', 'event': 'Accessed by TQAStage'} to the event log at 2025-01-31 06:51:31.622618.
[01/31/2025 06:51:31 AM] [DEBUG] [genailab.asset.dataset.state.DatasetState] [state] [access] : Dataset accessed by TQAStage at 2025-01-31 06:51:31.622608
[01/31/2025 06:51:31 AM] [DEBUG] [genailab.flow.base.stage.TQAStage] [stage] [_validate_dataframe_type] : Inside TQAStage: _validate_dataframe_type
[01/31/2025 06:51:31 AM] [DEBUG] [asyncio] [selector_events] [__init__] : Using selector: EpollSelector
[01/31/2025 06:51:34 AM] [ERROR] [genailab.flow.base.stage.TQAStage] [stage] [_run] : Error in task TQATask: Analyst._process_row() got an unexpected keyword argument 'meta'
[01/31/2025 06:51:34 AM] [ERROR] [Stage.run] [stage] [wrapper] : Exception occurred in Stage.run called with force=True
Error in task TQATask: Analyst._process_row() got an unexpected keyword argument 'meta'
Traceback (most recent call last):
  File "/home/john/projects/genailab/genailab/flow/feature/tqa/stage.py", line 94, in _run
    dataframe = task.run(dataframe)
  File "/home/john/projects/genailab/genailab/flow/feature/tqa/task.py", line 146, in run
    return self._analyst.analyze(data=data)
  File "/home/john/projects/genailab/genailab/flow/feature/tqa/task.py", line 366, in analyze
    results = data.apply(self._process_row, args=(function_words, nlp),
  File "/home/john/miniconda3/envs/genai/lib/python3.10/site-packages/pandas/core/frame.py", line 10374, in apply
    return op.apply().__finalize__(self, method="apply")
  File "/home/john/miniconda3/envs/genai/lib/python3.10/site-packages/pandas/core/apply.py", line 916, in apply
    return self.apply_standard()
  File "/home/john/miniconda3/envs/genai/lib/python3.10/site-packages/pandas/core/apply.py", line 1063, in apply_standard
    results, res_index = self.apply_series_generator()
  File "/home/john/miniconda3/envs/genai/lib/python3.10/site-packages/pandas/core/apply.py", line 1081, in apply_series_generator
    results[i] = self.func(v, *self.args, **self.kwargs)
TypeError: Analyst._process_row() got an unexpected keyword argument 'meta'

During handling of the above exception, another exception occurred:

Traceback (most recent call last):
  File "/home/john/projects/genailab/genailab/infra/service/logging/stage.py", line 58, in wrapper
    result = func(self, *args, **kwargs)
  File "/home/john/projects/genailab/genailab/flow/base/stage.py", line 147, in run
    return self._run()
  File "/home/john/projects/genailab/genailab/flow/feature/tqa/stage.py", line 97, in _run
    raise RuntimeError(f"Error in task {task.__class__.__name__}: {e}")
RuntimeError: Error in task TQATask: Analyst._process_row() got an unexpected keyword argument 'meta'
[01/31/2025 06:51:48 AM] [DEBUG] [genailab.infra.persist.repo.object.rao.RAO] [rao] [__init__] : RAO created at workspace/test/datasets/ral/
[01/31/2025 06:51:48 AM] [DEBUG] [genailab.infra.persist.repo.object.dao.DAO] [dao] [__init__] : DAO created at workspace/test/datasets/dal/
[01/31/2025 06:51:49 AM] [DEBUG] [genailab.flow.base.stage.TQAStage] [stage] [run] : Inside TQAStage: run
[01/31/2025 06:51:49 AM] [DEBUG] [genailab.flow.base.stage.TQAStage] [stage] [_dataset_exists] : Inside TQAStage: _dataset_exists
[01/31/2025 06:51:49 AM] [DEBUG] [genailab.flow.base.stage.TQAStage] [stage] [_fresh_cache_exists] : Inside TQAStage: _fresh_cache_exists
[01/31/2025 06:51:49 AM] [DEBUG] [genailab.flow.base.stage.TQAStage] [stage] [_get_dataset] : Inside TQAStage: _get_dataset
[01/31/2025 06:51:49 AM] [DEBUG] [genailab.flow.base.stage.TQAStage] [stage] [_dataset_exists] : Inside TQAStage: _dataset_exists
[01/31/2025 06:51:49 AM] [DEBUG] [genailab.flow.base.stage.TQAStage] [stage] [_fresh_cache_exists] : The target dataset cache for Feature Engineering Phase/Text Quality Analysis Stage does not exist in the repository.
[01/31/2025 06:51:49 AM] [DEBUG] [genailab.flow.base.stage.TQAStage] [stage] [_run] : Inside TQAStage: _run
[01/31/2025 06:51:49 AM] [DEBUG] [genailab.flow.base.stage.TQAStage] [stage] [_remove_dataset] : Inside TQAStage: _remove_dataset
[01/31/2025 06:51:49 AM] [DEBUG] [genailab.flow.base.stage.TQAStage] [stage] [_get_dataset] : Inside TQAStage: _get_dataset
[01/31/2025 06:51:49 AM] [DEBUG] [root] [factory] [get_reader] : Requesting a pandas_parquet reader from the DataFrameIOFactory
[01/31/2025 06:51:49 AM] [DEBUG] [genailab.infra.persist.repo.file.pandas.PandasDataFrameParquetReader] [pandas] [read] : PandasDataFrameParquetReader read from workspace/test/datasets/fal/dataprep/dataprep_clean_dataset_review.parquet
[01/31/2025 06:51:49 AM] [DEBUG] [genailab.asset.dataset.state.DatasetState] [state] [add_event] : Added {'timestamp': datetime.datetime(2025, 1, 31, 6, 51, 49, 653500), 'entity': 'TQAStage', 'event': 'Accessed by TQAStage'} to the event log at 2025-01-31 06:51:49.653502.
[01/31/2025 06:51:49 AM] [DEBUG] [genailab.asset.dataset.state.DatasetState] [state] [access] : Dataset accessed by TQAStage at 2025-01-31 06:51:49.653489
[01/31/2025 06:51:49 AM] [DEBUG] [genailab.flow.base.stage.TQAStage] [stage] [_validate_dataframe_type] : Inside TQAStage: _validate_dataframe_type
[01/31/2025 06:51:49 AM] [DEBUG] [asyncio] [selector_events] [__init__] : Using selector: EpollSelector
[01/31/2025 06:51:52 AM] [ERROR] [genailab.flow.base.stage.TQAStage] [stage] [_run] : Error in task TQATask: Analyst._process_row() got an unexpected keyword argument 'meta'
[01/31/2025 06:51:52 AM] [ERROR] [Stage.run] [stage] [wrapper] : Exception occurred in Stage.run called with force=True
Error in task TQATask: Analyst._process_row() got an unexpected keyword argument 'meta'
Traceback (most recent call last):
  File "/home/john/projects/genailab/genailab/flow/feature/tqa/stage.py", line 94, in _run
    dataframe = task.run(dataframe)
  File "/home/john/projects/genailab/genailab/flow/feature/tqa/task.py", line 146, in run
    return self._analyst.analyze(data=data)
  File "/home/john/projects/genailab/genailab/flow/feature/tqa/task.py", line 366, in analyze
    results = data.apply(self._process_row, args=(function_words, nlp),
  File "/home/john/miniconda3/envs/genai/lib/python3.10/site-packages/pandas/core/frame.py", line 10374, in apply
    return op.apply().__finalize__(self, method="apply")
  File "/home/john/miniconda3/envs/genai/lib/python3.10/site-packages/pandas/core/apply.py", line 916, in apply
    return self.apply_standard()
  File "/home/john/miniconda3/envs/genai/lib/python3.10/site-packages/pandas/core/apply.py", line 1063, in apply_standard
    results, res_index = self.apply_series_generator()
  File "/home/john/miniconda3/envs/genai/lib/python3.10/site-packages/pandas/core/apply.py", line 1081, in apply_series_generator
    results[i] = self.func(v, *self.args, **self.kwargs)
TypeError: Analyst._process_row() got an unexpected keyword argument 'meta'

During handling of the above exception, another exception occurred:

Traceback (most recent call last):
  File "/home/john/projects/genailab/genailab/infra/service/logging/stage.py", line 58, in wrapper
    result = func(self, *args, **kwargs)
  File "/home/john/projects/genailab/genailab/flow/base/stage.py", line 147, in run
    return self._run()
  File "/home/john/projects/genailab/genailab/flow/feature/tqa/stage.py", line 97, in _run
    raise RuntimeError(f"Error in task {task.__class__.__name__}: {e}")
RuntimeError: Error in task TQATask: Analyst._process_row() got an unexpected keyword argument 'meta'
[01/31/2025 06:56:30 AM] [DEBUG] [genailab.infra.persist.repo.object.rao.RAO] [rao] [__init__] : RAO created at workspace/test/datasets/ral/
[01/31/2025 06:56:30 AM] [DEBUG] [genailab.infra.persist.repo.object.dao.DAO] [dao] [__init__] : DAO created at workspace/test/datasets/dal/
[01/31/2025 06:56:31 AM] [DEBUG] [genailab.flow.base.stage.TQAStage] [stage] [run] : Inside TQAStage: run
[01/31/2025 06:56:31 AM] [DEBUG] [genailab.flow.base.stage.TQAStage] [stage] [_dataset_exists] : Inside TQAStage: _dataset_exists
[01/31/2025 06:56:31 AM] [DEBUG] [genailab.flow.base.stage.TQAStage] [stage] [_fresh_cache_exists] : Inside TQAStage: _fresh_cache_exists
[01/31/2025 06:56:31 AM] [DEBUG] [genailab.flow.base.stage.TQAStage] [stage] [_get_dataset] : Inside TQAStage: _get_dataset
[01/31/2025 06:56:31 AM] [DEBUG] [genailab.flow.base.stage.TQAStage] [stage] [_dataset_exists] : Inside TQAStage: _dataset_exists
[01/31/2025 06:56:31 AM] [DEBUG] [genailab.flow.base.stage.TQAStage] [stage] [_fresh_cache_exists] : The target dataset cache for Feature Engineering Phase/Text Quality Analysis Stage does not exist in the repository.
[01/31/2025 06:56:31 AM] [DEBUG] [genailab.flow.base.stage.TQAStage] [stage] [_run] : Inside TQAStage: _run
[01/31/2025 06:56:31 AM] [DEBUG] [genailab.flow.base.stage.TQAStage] [stage] [_remove_dataset] : Inside TQAStage: _remove_dataset
[01/31/2025 06:56:31 AM] [DEBUG] [genailab.flow.base.stage.TQAStage] [stage] [_get_dataset] : Inside TQAStage: _get_dataset
[01/31/2025 06:56:31 AM] [DEBUG] [root] [factory] [get_reader] : Requesting a pandas_parquet reader from the DataFrameIOFactory
[01/31/2025 06:56:31 AM] [DEBUG] [genailab.infra.persist.repo.file.pandas.PandasDataFrameParquetReader] [pandas] [read] : PandasDataFrameParquetReader read from workspace/test/datasets/fal/dataprep/dataprep_clean_dataset_review.parquet
[01/31/2025 06:56:31 AM] [DEBUG] [genailab.asset.dataset.state.DatasetState] [state] [add_event] : Added {'timestamp': datetime.datetime(2025, 1, 31, 6, 56, 31, 275195), 'entity': 'TQAStage', 'event': 'Accessed by TQAStage'} to the event log at 2025-01-31 06:56:31.275199.
[01/31/2025 06:56:31 AM] [DEBUG] [genailab.asset.dataset.state.DatasetState] [state] [access] : Dataset accessed by TQAStage at 2025-01-31 06:56:31.275185
[01/31/2025 06:56:31 AM] [DEBUG] [genailab.flow.base.stage.TQAStage] [stage] [_validate_dataframe_type] : Inside TQAStage: _validate_dataframe_type
[01/31/2025 06:56:31 AM] [DEBUG] [asyncio] [selector_events] [__init__] : Using selector: EpollSelector
[01/31/2025 06:56:33 AM] [ERROR] [genailab.flow.base.stage.TQAStage] [stage] [_run] : Error in task TQATask: TQAnalystDask.analyze.<locals>.<lambda>() got an unexpected keyword argument 'meta'
[01/31/2025 06:56:33 AM] [ERROR] [Stage.run] [stage] [wrapper] : Exception occurred in Stage.run called with force=True
Error in task TQATask: TQAnalystDask.analyze.<locals>.<lambda>() got an unexpected keyword argument 'meta'
Traceback (most recent call last):
  File "/home/john/projects/genailab/genailab/flow/feature/tqa/stage.py", line 94, in _run
    dataframe = task.run(dataframe)
  File "/home/john/projects/genailab/genailab/flow/feature/tqa/task.py", line 146, in run
    return self._analyst.analyze(data=data)
  File "/home/john/projects/genailab/genailab/flow/feature/tqa/task.py", line 366, in analyze
    results = data.apply(lambda row:
  File "/home/john/miniconda3/envs/genai/lib/python3.10/site-packages/pandas/core/frame.py", line 10374, in apply
    return op.apply().__finalize__(self, method="apply")
  File "/home/john/miniconda3/envs/genai/lib/python3.10/site-packages/pandas/core/apply.py", line 916, in apply
    return self.apply_standard()
  File "/home/john/miniconda3/envs/genai/lib/python3.10/site-packages/pandas/core/apply.py", line 1063, in apply_standard
    results, res_index = self.apply_series_generator()
  File "/home/john/miniconda3/envs/genai/lib/python3.10/site-packages/pandas/core/apply.py", line 1081, in apply_series_generator
    results[i] = self.func(v, *self.args, **self.kwargs)
TypeError: TQAnalystDask.analyze.<locals>.<lambda>() got an unexpected keyword argument 'meta'

During handling of the above exception, another exception occurred:

Traceback (most recent call last):
  File "/home/john/projects/genailab/genailab/infra/service/logging/stage.py", line 58, in wrapper
    result = func(self, *args, **kwargs)
  File "/home/john/projects/genailab/genailab/flow/base/stage.py", line 147, in run
    return self._run()
  File "/home/john/projects/genailab/genailab/flow/feature/tqa/stage.py", line 97, in _run
    raise RuntimeError(f"Error in task {task.__class__.__name__}: {e}")
RuntimeError: Error in task TQATask: TQAnalystDask.analyze.<locals>.<lambda>() got an unexpected keyword argument 'meta'
[01/31/2025 07:02:23 AM] [DEBUG] [genailab.infra.persist.repo.object.rao.RAO] [rao] [__init__] : RAO created at workspace/test/datasets/ral/
[01/31/2025 07:02:23 AM] [DEBUG] [genailab.infra.persist.repo.object.dao.DAO] [dao] [__init__] : DAO created at workspace/test/datasets/dal/
[01/31/2025 07:02:24 AM] [DEBUG] [genailab.flow.base.stage.TQAStage] [stage] [run] : Inside TQAStage: run
[01/31/2025 07:02:24 AM] [DEBUG] [genailab.flow.base.stage.TQAStage] [stage] [_dataset_exists] : Inside TQAStage: _dataset_exists
[01/31/2025 07:02:24 AM] [DEBUG] [genailab.flow.base.stage.TQAStage] [stage] [_fresh_cache_exists] : Inside TQAStage: _fresh_cache_exists
[01/31/2025 07:02:24 AM] [DEBUG] [genailab.flow.base.stage.TQAStage] [stage] [_get_dataset] : Inside TQAStage: _get_dataset
[01/31/2025 07:02:24 AM] [DEBUG] [genailab.flow.base.stage.TQAStage] [stage] [_dataset_exists] : Inside TQAStage: _dataset_exists
[01/31/2025 07:02:24 AM] [DEBUG] [genailab.flow.base.stage.TQAStage] [stage] [_fresh_cache_exists] : The target dataset cache for Feature Engineering Phase/Text Quality Analysis Stage does not exist in the repository.
[01/31/2025 07:02:24 AM] [DEBUG] [genailab.flow.base.stage.TQAStage] [stage] [_run] : Inside TQAStage: _run
[01/31/2025 07:02:24 AM] [DEBUG] [genailab.flow.base.stage.TQAStage] [stage] [_remove_dataset] : Inside TQAStage: _remove_dataset
[01/31/2025 07:02:24 AM] [DEBUG] [genailab.flow.base.stage.TQAStage] [stage] [_get_dataset] : Inside TQAStage: _get_dataset
[01/31/2025 07:02:24 AM] [DEBUG] [root] [factory] [get_reader] : Requesting a pandas_parquet reader from the DataFrameIOFactory
[01/31/2025 07:02:24 AM] [DEBUG] [genailab.infra.persist.repo.file.pandas.PandasDataFrameParquetReader] [pandas] [read] : PandasDataFrameParquetReader read from workspace/test/datasets/fal/dataprep/dataprep_clean_dataset_review.parquet
[01/31/2025 07:02:24 AM] [DEBUG] [genailab.asset.dataset.state.DatasetState] [state] [add_event] : Added {'timestamp': datetime.datetime(2025, 1, 31, 7, 2, 24, 595335), 'entity': 'TQAStage', 'event': 'Accessed by TQAStage'} to the event log at 2025-01-31 07:02:24.595340.
[01/31/2025 07:02:24 AM] [DEBUG] [genailab.asset.dataset.state.DatasetState] [state] [access] : Dataset accessed by TQAStage at 2025-01-31 07:02:24.595325
[01/31/2025 07:02:24 AM] [DEBUG] [genailab.flow.base.stage.TQAStage] [stage] [_validate_dataframe_type] : Inside TQAStage: _validate_dataframe_type
[01/31/2025 07:02:24 AM] [DEBUG] [asyncio] [selector_events] [__init__] : Using selector: EpollSelector
[01/31/2025 07:02:27 AM] [ERROR] [genailab.flow.base.stage.TQAStage] [stage] [_run] : Error in task TQATask: TQAnalystDask.analyze.<locals>.<lambda>() got an unexpected keyword argument 'meta'
[01/31/2025 07:02:27 AM] [ERROR] [Stage.run] [stage] [wrapper] : Exception occurred in Stage.run called with force=True
Error in task TQATask: TQAnalystDask.analyze.<locals>.<lambda>() got an unexpected keyword argument 'meta'
Traceback (most recent call last):
  File "/home/john/projects/genailab/genailab/flow/feature/tqa/stage.py", line 94, in _run
    dataframe = task.run(dataframe)
  File "/home/john/projects/genailab/genailab/flow/feature/tqa/task.py", line 146, in run
    return self._analyst.analyze(data=data)
  File "/home/john/projects/genailab/genailab/flow/feature/tqa/task.py", line 366, in analyze
    results = data.apply(lambda row: self._process_row(row, function_words, nlp),
  File "/home/john/miniconda3/envs/genai/lib/python3.10/site-packages/pandas/core/frame.py", line 10374, in apply
    return op.apply().__finalize__(self, method="apply")
  File "/home/john/miniconda3/envs/genai/lib/python3.10/site-packages/pandas/core/apply.py", line 916, in apply
    return self.apply_standard()
  File "/home/john/miniconda3/envs/genai/lib/python3.10/site-packages/pandas/core/apply.py", line 1063, in apply_standard
    results, res_index = self.apply_series_generator()
  File "/home/john/miniconda3/envs/genai/lib/python3.10/site-packages/pandas/core/apply.py", line 1081, in apply_series_generator
    results[i] = self.func(v, *self.args, **self.kwargs)
TypeError: TQAnalystDask.analyze.<locals>.<lambda>() got an unexpected keyword argument 'meta'

During handling of the above exception, another exception occurred:

Traceback (most recent call last):
  File "/home/john/projects/genailab/genailab/infra/service/logging/stage.py", line 58, in wrapper
    result = func(self, *args, **kwargs)
  File "/home/john/projects/genailab/genailab/flow/base/stage.py", line 147, in run
    return self._run()
  File "/home/john/projects/genailab/genailab/flow/feature/tqa/stage.py", line 97, in _run
    raise RuntimeError(f"Error in task {task.__class__.__name__}: {e}")
RuntimeError: Error in task TQATask: TQAnalystDask.analyze.<locals>.<lambda>() got an unexpected keyword argument 'meta'
[01/31/2025 07:06:38 AM] [DEBUG] [genailab.infra.persist.repo.object.rao.RAO] [rao] [__init__] : RAO created at workspace/test/datasets/ral/
[01/31/2025 07:06:38 AM] [DEBUG] [genailab.infra.persist.repo.object.dao.DAO] [dao] [__init__] : DAO created at workspace/test/datasets/dal/
[01/31/2025 07:06:39 AM] [DEBUG] [genailab.flow.base.stage.TQAStage] [stage] [run] : Inside TQAStage: run
[01/31/2025 07:06:39 AM] [DEBUG] [genailab.flow.base.stage.TQAStage] [stage] [_dataset_exists] : Inside TQAStage: _dataset_exists
[01/31/2025 07:06:39 AM] [DEBUG] [genailab.flow.base.stage.TQAStage] [stage] [_fresh_cache_exists] : Inside TQAStage: _fresh_cache_exists
[01/31/2025 07:06:39 AM] [DEBUG] [genailab.flow.base.stage.TQAStage] [stage] [_get_dataset] : Inside TQAStage: _get_dataset
[01/31/2025 07:06:39 AM] [DEBUG] [genailab.flow.base.stage.TQAStage] [stage] [_dataset_exists] : Inside TQAStage: _dataset_exists
[01/31/2025 07:06:39 AM] [DEBUG] [genailab.flow.base.stage.TQAStage] [stage] [_fresh_cache_exists] : The target dataset cache for Feature Engineering Phase/Text Quality Analysis Stage does not exist in the repository.
[01/31/2025 07:06:39 AM] [DEBUG] [genailab.flow.base.stage.TQAStage] [stage] [_run] : Inside TQAStage: _run
[01/31/2025 07:06:39 AM] [DEBUG] [genailab.flow.base.stage.TQAStage] [stage] [_remove_dataset] : Inside TQAStage: _remove_dataset
[01/31/2025 07:06:39 AM] [DEBUG] [genailab.flow.base.stage.TQAStage] [stage] [_get_dataset] : Inside TQAStage: _get_dataset
[01/31/2025 07:06:39 AM] [DEBUG] [root] [factory] [get_reader] : Requesting a dask_parquet reader from the DataFrameIOFactory
[01/31/2025 07:06:39 AM] [ERROR] [genailab.flow.base.stage.TQAStage] [stage] [_get_dataset] : Unexpected exception occurred while getting dataset dataprep_clean_dataset_review from the repository.
Exception occurred while reading a Parquet file from workspace/test/datasets/fal/dataprep/dataprep_clean_dataset_review.parquet.
An error occurred while calling the read_parquet method registered to the pandas backend.
Original Message: pyarrow>=15.0.0 is required to use the pyarrow filesystem.
Original exception: An error occurred while calling the read_parquet method registered to the pandas backend.
Original Message: pyarrow>=15.0.0 is required to use the pyarrow filesystem.
Traceback (most recent call last):
  File "/home/john/miniconda3/envs/genai/lib/python3.10/site-packages/dask/backends.py", line 140, in wrapper
    return func(*args, **kwargs)
  File "/home/john/miniconda3/envs/genai/lib/python3.10/site-packages/dask/dataframe/dask_expr/_collection.py", line 5324, in read_parquet
    raise ValueError(
ValueError: pyarrow>=15.0.0 is required to use the pyarrow filesystem.

The above exception was the direct cause of the following exception:

Traceback (most recent call last):
  File "/home/john/projects/genailab/genailab/infra/persist/repo/file/dask.py", line 57, in read
    df = dd.read_parquet(path=filepath, **self._kwargs)
  File "/home/john/miniconda3/envs/genai/lib/python3.10/site-packages/dask/backends.py", line 151, in wrapper
    raise exc from e
ValueError: An error occurred while calling the read_parquet method registered to the pandas backend.
Original Message: pyarrow>=15.0.0 is required to use the pyarrow filesystem.

The above exception was the direct cause of the following exception:

Traceback (most recent call last):
  File "/home/john/projects/genailab/genailab/flow/base/stage.py", line 255, in _get_dataset
    dataset = self._repo.get(
  File "/home/john/projects/genailab/genailab/infra/persist/repo/dataset.py", line 165, in get
    df = self._fao.read(filepath=dataset.file.path, dftype=dftype, spark=spark)
  File "/home/john/projects/genailab/genailab/infra/persist/repo/file/fao.py", line 130, in read
    return reader.read(filepath=filepath, spark=spark)
  File "/home/john/projects/genailab/genailab/infra/persist/repo/file/dask.py", line 68, in read
    raise FileIOException(msg, e) from e
genailab.infra.exception.file.FileIOException: Exception occurred while reading a Parquet file from workspace/test/datasets/fal/dataprep/dataprep_clean_dataset_review.parquet.
An error occurred while calling the read_parquet method registered to the pandas backend.
Original Message: pyarrow>=15.0.0 is required to use the pyarrow filesystem.
Original exception: An error occurred while calling the read_parquet method registered to the pandas backend.
Original Message: pyarrow>=15.0.0 is required to use the pyarrow filesystem.
[01/31/2025 07:06:39 AM] [ERROR] [Stage.run] [stage] [wrapper] : Exception occurred in Stage.run called with force=True
Unexpected exception occurred while getting dataset dataprep_clean_dataset_review from the repository.
Exception occurred while reading a Parquet file from workspace/test/datasets/fal/dataprep/dataprep_clean_dataset_review.parquet.
An error occurred while calling the read_parquet method registered to the pandas backend.
Original Message: pyarrow>=15.0.0 is required to use the pyarrow filesystem.
Original exception: An error occurred while calling the read_parquet method registered to the pandas backend.
Original Message: pyarrow>=15.0.0 is required to use the pyarrow filesystem.
Traceback (most recent call last):
  File "/home/john/miniconda3/envs/genai/lib/python3.10/site-packages/dask/backends.py", line 140, in wrapper
    return func(*args, **kwargs)
  File "/home/john/miniconda3/envs/genai/lib/python3.10/site-packages/dask/dataframe/dask_expr/_collection.py", line 5324, in read_parquet
    raise ValueError(
ValueError: pyarrow>=15.0.0 is required to use the pyarrow filesystem.

The above exception was the direct cause of the following exception:

Traceback (most recent call last):
  File "/home/john/projects/genailab/genailab/infra/persist/repo/file/dask.py", line 57, in read
    df = dd.read_parquet(path=filepath, **self._kwargs)
  File "/home/john/miniconda3/envs/genai/lib/python3.10/site-packages/dask/backends.py", line 151, in wrapper
    raise exc from e
ValueError: An error occurred while calling the read_parquet method registered to the pandas backend.
Original Message: pyarrow>=15.0.0 is required to use the pyarrow filesystem.

The above exception was the direct cause of the following exception:

Traceback (most recent call last):
  File "/home/john/projects/genailab/genailab/flow/base/stage.py", line 255, in _get_dataset
    dataset = self._repo.get(
  File "/home/john/projects/genailab/genailab/infra/persist/repo/dataset.py", line 165, in get
    df = self._fao.read(filepath=dataset.file.path, dftype=dftype, spark=spark)
  File "/home/john/projects/genailab/genailab/infra/persist/repo/file/fao.py", line 130, in read
    return reader.read(filepath=filepath, spark=spark)
  File "/home/john/projects/genailab/genailab/infra/persist/repo/file/dask.py", line 68, in read
    raise FileIOException(msg, e) from e
genailab.infra.exception.file.FileIOException: Exception occurred while reading a Parquet file from workspace/test/datasets/fal/dataprep/dataprep_clean_dataset_review.parquet.
An error occurred while calling the read_parquet method registered to the pandas backend.
Original Message: pyarrow>=15.0.0 is required to use the pyarrow filesystem.
Original exception: An error occurred while calling the read_parquet method registered to the pandas backend.
Original Message: pyarrow>=15.0.0 is required to use the pyarrow filesystem.

During handling of the above exception, another exception occurred:

Traceback (most recent call last):
  File "/home/john/projects/genailab/genailab/infra/service/logging/stage.py", line 58, in wrapper
    result = func(self, *args, **kwargs)
  File "/home/john/projects/genailab/genailab/flow/base/stage.py", line 147, in run
    return self._run()
  File "/home/john/projects/genailab/genailab/flow/feature/tqa/stage.py", line 86, in _run
    source = self._get_dataset(config=self._source_config)
  File "/home/john/projects/genailab/genailab/flow/base/stage.py", line 271, in _get_dataset
    raise Exception(msg)
Exception: Unexpected exception occurred while getting dataset dataprep_clean_dataset_review from the repository.
Exception occurred while reading a Parquet file from workspace/test/datasets/fal/dataprep/dataprep_clean_dataset_review.parquet.
An error occurred while calling the read_parquet method registered to the pandas backend.
Original Message: pyarrow>=15.0.0 is required to use the pyarrow filesystem.
Original exception: An error occurred while calling the read_parquet method registered to the pandas backend.
Original Message: pyarrow>=15.0.0 is required to use the pyarrow filesystem.
[01/31/2025 07:10:12 AM] [DEBUG] [genailab.infra.persist.repo.object.rao.RAO] [rao] [__init__] : RAO created at workspace/test/datasets/ral/
[01/31/2025 07:10:12 AM] [DEBUG] [genailab.infra.persist.repo.object.dao.DAO] [dao] [__init__] : DAO created at workspace/test/datasets/dal/
[01/31/2025 07:10:13 AM] [DEBUG] [genailab.flow.base.stage.TQAStage] [stage] [run] : Inside TQAStage: run
[01/31/2025 07:10:13 AM] [DEBUG] [genailab.flow.base.stage.TQAStage] [stage] [_dataset_exists] : Inside TQAStage: _dataset_exists
[01/31/2025 07:10:13 AM] [DEBUG] [genailab.flow.base.stage.TQAStage] [stage] [_fresh_cache_exists] : Inside TQAStage: _fresh_cache_exists
[01/31/2025 07:10:13 AM] [DEBUG] [genailab.flow.base.stage.TQAStage] [stage] [_get_dataset] : Inside TQAStage: _get_dataset
[01/31/2025 07:10:13 AM] [DEBUG] [genailab.flow.base.stage.TQAStage] [stage] [_dataset_exists] : Inside TQAStage: _dataset_exists
[01/31/2025 07:10:13 AM] [DEBUG] [genailab.flow.base.stage.TQAStage] [stage] [_fresh_cache_exists] : The target dataset cache for Feature Engineering Phase/Text Quality Analysis Stage does not exist in the repository.
[01/31/2025 07:10:13 AM] [DEBUG] [genailab.flow.base.stage.TQAStage] [stage] [_run] : Inside TQAStage: _run
[01/31/2025 07:10:13 AM] [DEBUG] [genailab.flow.base.stage.TQAStage] [stage] [_remove_dataset] : Inside TQAStage: _remove_dataset
[01/31/2025 07:10:13 AM] [DEBUG] [genailab.flow.base.stage.TQAStage] [stage] [_get_dataset] : Inside TQAStage: _get_dataset
[01/31/2025 07:10:13 AM] [DEBUG] [root] [factory] [get_reader] : Requesting a dask_parquet reader from the DataFrameIOFactory
[01/31/2025 07:10:13 AM] [ERROR] [genailab.flow.base.stage.TQAStage] [stage] [_get_dataset] : Unexpected exception occurred while getting dataset dataprep_clean_dataset_review from the repository.
Exception occurred while reading a Parquet file from workspace/test/datasets/fal/dataprep/dataprep_clean_dataset_review.parquet.
An error occurred while calling the read_parquet method registered to the pandas backend.
Original Message: pyarrow>=15.0.0 is required to use the pyarrow filesystem.
Original exception: An error occurred while calling the read_parquet method registered to the pandas backend.
Original Message: pyarrow>=15.0.0 is required to use the pyarrow filesystem.
Traceback (most recent call last):
  File "/home/john/miniconda3/envs/genai/lib/python3.10/site-packages/dask/backends.py", line 140, in wrapper
    return func(*args, **kwargs)
  File "/home/john/miniconda3/envs/genai/lib/python3.10/site-packages/dask/dataframe/dask_expr/_collection.py", line 5324, in read_parquet
    raise ValueError(
ValueError: pyarrow>=15.0.0 is required to use the pyarrow filesystem.

The above exception was the direct cause of the following exception:

Traceback (most recent call last):
  File "/home/john/projects/genailab/genailab/infra/persist/repo/file/dask.py", line 57, in read
    df = dd.read_parquet(path=filepath, **self._kwargs)
  File "/home/john/miniconda3/envs/genai/lib/python3.10/site-packages/dask/backends.py", line 151, in wrapper
    raise exc from e
ValueError: An error occurred while calling the read_parquet method registered to the pandas backend.
Original Message: pyarrow>=15.0.0 is required to use the pyarrow filesystem.

The above exception was the direct cause of the following exception:

Traceback (most recent call last):
  File "/home/john/projects/genailab/genailab/flow/base/stage.py", line 255, in _get_dataset
    dataset = self._repo.get(
  File "/home/john/projects/genailab/genailab/infra/persist/repo/dataset.py", line 165, in get
    df = self._fao.read(filepath=dataset.file.path, dftype=dftype, spark=spark)
  File "/home/john/projects/genailab/genailab/infra/persist/repo/file/fao.py", line 130, in read
    return reader.read(filepath=filepath, spark=spark)
  File "/home/john/projects/genailab/genailab/infra/persist/repo/file/dask.py", line 68, in read
    raise FileIOException(msg, e) from e
genailab.infra.exception.file.FileIOException: Exception occurred while reading a Parquet file from workspace/test/datasets/fal/dataprep/dataprep_clean_dataset_review.parquet.
An error occurred while calling the read_parquet method registered to the pandas backend.
Original Message: pyarrow>=15.0.0 is required to use the pyarrow filesystem.
Original exception: An error occurred while calling the read_parquet method registered to the pandas backend.
Original Message: pyarrow>=15.0.0 is required to use the pyarrow filesystem.
[01/31/2025 07:10:13 AM] [ERROR] [Stage.run] [stage] [wrapper] : Exception occurred in Stage.run called with force=True
Unexpected exception occurred while getting dataset dataprep_clean_dataset_review from the repository.
Exception occurred while reading a Parquet file from workspace/test/datasets/fal/dataprep/dataprep_clean_dataset_review.parquet.
An error occurred while calling the read_parquet method registered to the pandas backend.
Original Message: pyarrow>=15.0.0 is required to use the pyarrow filesystem.
Original exception: An error occurred while calling the read_parquet method registered to the pandas backend.
Original Message: pyarrow>=15.0.0 is required to use the pyarrow filesystem.
Traceback (most recent call last):
  File "/home/john/miniconda3/envs/genai/lib/python3.10/site-packages/dask/backends.py", line 140, in wrapper
    return func(*args, **kwargs)
  File "/home/john/miniconda3/envs/genai/lib/python3.10/site-packages/dask/dataframe/dask_expr/_collection.py", line 5324, in read_parquet
    raise ValueError(
ValueError: pyarrow>=15.0.0 is required to use the pyarrow filesystem.

The above exception was the direct cause of the following exception:

Traceback (most recent call last):
  File "/home/john/projects/genailab/genailab/infra/persist/repo/file/dask.py", line 57, in read
    df = dd.read_parquet(path=filepath, **self._kwargs)
  File "/home/john/miniconda3/envs/genai/lib/python3.10/site-packages/dask/backends.py", line 151, in wrapper
    raise exc from e
ValueError: An error occurred while calling the read_parquet method registered to the pandas backend.
Original Message: pyarrow>=15.0.0 is required to use the pyarrow filesystem.

The above exception was the direct cause of the following exception:

Traceback (most recent call last):
  File "/home/john/projects/genailab/genailab/flow/base/stage.py", line 255, in _get_dataset
    dataset = self._repo.get(
  File "/home/john/projects/genailab/genailab/infra/persist/repo/dataset.py", line 165, in get
    df = self._fao.read(filepath=dataset.file.path, dftype=dftype, spark=spark)
  File "/home/john/projects/genailab/genailab/infra/persist/repo/file/fao.py", line 130, in read
    return reader.read(filepath=filepath, spark=spark)
  File "/home/john/projects/genailab/genailab/infra/persist/repo/file/dask.py", line 68, in read
    raise FileIOException(msg, e) from e
genailab.infra.exception.file.FileIOException: Exception occurred while reading a Parquet file from workspace/test/datasets/fal/dataprep/dataprep_clean_dataset_review.parquet.
An error occurred while calling the read_parquet method registered to the pandas backend.
Original Message: pyarrow>=15.0.0 is required to use the pyarrow filesystem.
Original exception: An error occurred while calling the read_parquet method registered to the pandas backend.
Original Message: pyarrow>=15.0.0 is required to use the pyarrow filesystem.

During handling of the above exception, another exception occurred:

Traceback (most recent call last):
  File "/home/john/projects/genailab/genailab/infra/service/logging/stage.py", line 58, in wrapper
    result = func(self, *args, **kwargs)
  File "/home/john/projects/genailab/genailab/flow/base/stage.py", line 147, in run
    return self._run()
  File "/home/john/projects/genailab/genailab/flow/feature/tqa/stage.py", line 86, in _run
    source = self._get_dataset(config=self._source_config)
  File "/home/john/projects/genailab/genailab/flow/base/stage.py", line 271, in _get_dataset
    raise Exception(msg)
Exception: Unexpected exception occurred while getting dataset dataprep_clean_dataset_review from the repository.
Exception occurred while reading a Parquet file from workspace/test/datasets/fal/dataprep/dataprep_clean_dataset_review.parquet.
An error occurred while calling the read_parquet method registered to the pandas backend.
Original Message: pyarrow>=15.0.0 is required to use the pyarrow filesystem.
Original exception: An error occurred while calling the read_parquet method registered to the pandas backend.
Original Message: pyarrow>=15.0.0 is required to use the pyarrow filesystem.
[01/31/2025 07:22:58 AM] [DEBUG] [genailab.infra.persist.repo.object.rao.RAO] [rao] [__init__] : RAO created at workspace/test/datasets/ral/
[01/31/2025 07:22:59 AM] [DEBUG] [genailab.infra.persist.repo.object.dao.DAO] [dao] [__init__] : DAO created at workspace/test/datasets/dal/
[01/31/2025 07:22:59 AM] [DEBUG] [genailab.flow.base.stage.TQAStage] [stage] [run] : Inside TQAStage: run
[01/31/2025 07:22:59 AM] [DEBUG] [genailab.flow.base.stage.TQAStage] [stage] [_dataset_exists] : Inside TQAStage: _dataset_exists
[01/31/2025 07:22:59 AM] [DEBUG] [genailab.flow.base.stage.TQAStage] [stage] [_fresh_cache_exists] : Inside TQAStage: _fresh_cache_exists
[01/31/2025 07:22:59 AM] [DEBUG] [genailab.flow.base.stage.TQAStage] [stage] [_get_dataset] : Inside TQAStage: _get_dataset
[01/31/2025 07:22:59 AM] [DEBUG] [genailab.flow.base.stage.TQAStage] [stage] [_dataset_exists] : Inside TQAStage: _dataset_exists
[01/31/2025 07:22:59 AM] [DEBUG] [genailab.flow.base.stage.TQAStage] [stage] [_fresh_cache_exists] : The target dataset cache for Feature Engineering Phase/Text Quality Analysis Stage does not exist in the repository.
[01/31/2025 07:22:59 AM] [DEBUG] [genailab.flow.base.stage.TQAStage] [stage] [_run] : Inside TQAStage: _run
[01/31/2025 07:22:59 AM] [DEBUG] [genailab.flow.base.stage.TQAStage] [stage] [_remove_dataset] : Inside TQAStage: _remove_dataset
[01/31/2025 07:22:59 AM] [DEBUG] [genailab.flow.base.stage.TQAStage] [stage] [_get_dataset] : Inside TQAStage: _get_dataset
[01/31/2025 07:22:59 AM] [DEBUG] [root] [factory] [get_reader] : Requesting a dask_parquet reader from the DataFrameIOFactory
[01/31/2025 07:22:59 AM] [ERROR] [genailab.flow.base.stage.TQAStage] [stage] [_get_dataset] : Unexpected exception occurred while getting dataset dataprep_clean_dataset_review from the repository.
Exception occurred while reading a Parquet file from workspace/test/datasets/fal/dataprep/dataprep_clean_dataset_review.parquet.
An error occurred while calling the read_parquet method registered to the pandas backend.
Original Message: pyarrow>=15.0.0 is required to use the pyarrow filesystem.
Original exception: An error occurred while calling the read_parquet method registered to the pandas backend.
Original Message: pyarrow>=15.0.0 is required to use the pyarrow filesystem.
Traceback (most recent call last):
  File "/home/john/miniconda3/envs/genai/lib/python3.10/site-packages/dask/backends.py", line 140, in wrapper
    return func(*args, **kwargs)
  File "/home/john/miniconda3/envs/genai/lib/python3.10/site-packages/dask/dataframe/dask_expr/_collection.py", line 5324, in read_parquet
    raise ValueError(
ValueError: pyarrow>=15.0.0 is required to use the pyarrow filesystem.

The above exception was the direct cause of the following exception:

Traceback (most recent call last):
  File "/home/john/projects/genailab/genailab/infra/persist/repo/file/dask.py", line 57, in read
    df = dd.read_parquet(path=filepath, **self._kwargs)
  File "/home/john/miniconda3/envs/genai/lib/python3.10/site-packages/dask/backends.py", line 151, in wrapper
    raise exc from e
ValueError: An error occurred while calling the read_parquet method registered to the pandas backend.
Original Message: pyarrow>=15.0.0 is required to use the pyarrow filesystem.

The above exception was the direct cause of the following exception:

Traceback (most recent call last):
  File "/home/john/projects/genailab/genailab/flow/base/stage.py", line 255, in _get_dataset
    dataset = self._repo.get(
  File "/home/john/projects/genailab/genailab/infra/persist/repo/dataset.py", line 165, in get
    df = self._fao.read(filepath=dataset.file.path, dftype=dftype, spark=spark)
  File "/home/john/projects/genailab/genailab/infra/persist/repo/file/fao.py", line 130, in read
    return reader.read(filepath=filepath, spark=spark)
  File "/home/john/projects/genailab/genailab/infra/persist/repo/file/dask.py", line 68, in read
    raise FileIOException(msg, e) from e
genailab.infra.exception.file.FileIOException: Exception occurred while reading a Parquet file from workspace/test/datasets/fal/dataprep/dataprep_clean_dataset_review.parquet.
An error occurred while calling the read_parquet method registered to the pandas backend.
Original Message: pyarrow>=15.0.0 is required to use the pyarrow filesystem.
Original exception: An error occurred while calling the read_parquet method registered to the pandas backend.
Original Message: pyarrow>=15.0.0 is required to use the pyarrow filesystem.
[01/31/2025 07:22:59 AM] [ERROR] [Stage.run] [stage] [wrapper] : Exception occurred in Stage.run called with force=True
Unexpected exception occurred while getting dataset dataprep_clean_dataset_review from the repository.
Exception occurred while reading a Parquet file from workspace/test/datasets/fal/dataprep/dataprep_clean_dataset_review.parquet.
An error occurred while calling the read_parquet method registered to the pandas backend.
Original Message: pyarrow>=15.0.0 is required to use the pyarrow filesystem.
Original exception: An error occurred while calling the read_parquet method registered to the pandas backend.
Original Message: pyarrow>=15.0.0 is required to use the pyarrow filesystem.
Traceback (most recent call last):
  File "/home/john/miniconda3/envs/genai/lib/python3.10/site-packages/dask/backends.py", line 140, in wrapper
    return func(*args, **kwargs)
  File "/home/john/miniconda3/envs/genai/lib/python3.10/site-packages/dask/dataframe/dask_expr/_collection.py", line 5324, in read_parquet
    raise ValueError(
ValueError: pyarrow>=15.0.0 is required to use the pyarrow filesystem.

The above exception was the direct cause of the following exception:

Traceback (most recent call last):
  File "/home/john/projects/genailab/genailab/infra/persist/repo/file/dask.py", line 57, in read
    df = dd.read_parquet(path=filepath, **self._kwargs)
  File "/home/john/miniconda3/envs/genai/lib/python3.10/site-packages/dask/backends.py", line 151, in wrapper
    raise exc from e
ValueError: An error occurred while calling the read_parquet method registered to the pandas backend.
Original Message: pyarrow>=15.0.0 is required to use the pyarrow filesystem.

The above exception was the direct cause of the following exception:

Traceback (most recent call last):
  File "/home/john/projects/genailab/genailab/flow/base/stage.py", line 255, in _get_dataset
    dataset = self._repo.get(
  File "/home/john/projects/genailab/genailab/infra/persist/repo/dataset.py", line 165, in get
    df = self._fao.read(filepath=dataset.file.path, dftype=dftype, spark=spark)
  File "/home/john/projects/genailab/genailab/infra/persist/repo/file/fao.py", line 130, in read
    return reader.read(filepath=filepath, spark=spark)
  File "/home/john/projects/genailab/genailab/infra/persist/repo/file/dask.py", line 68, in read
    raise FileIOException(msg, e) from e
genailab.infra.exception.file.FileIOException: Exception occurred while reading a Parquet file from workspace/test/datasets/fal/dataprep/dataprep_clean_dataset_review.parquet.
An error occurred while calling the read_parquet method registered to the pandas backend.
Original Message: pyarrow>=15.0.0 is required to use the pyarrow filesystem.
Original exception: An error occurred while calling the read_parquet method registered to the pandas backend.
Original Message: pyarrow>=15.0.0 is required to use the pyarrow filesystem.

During handling of the above exception, another exception occurred:

Traceback (most recent call last):
  File "/home/john/projects/genailab/genailab/infra/service/logging/stage.py", line 58, in wrapper
    result = func(self, *args, **kwargs)
  File "/home/john/projects/genailab/genailab/flow/base/stage.py", line 147, in run
    return self._run()
  File "/home/john/projects/genailab/genailab/flow/feature/tqa/stage.py", line 86, in _run
    source = self._get_dataset(config=self._source_config)
  File "/home/john/projects/genailab/genailab/flow/base/stage.py", line 271, in _get_dataset
    raise Exception(msg)
Exception: Unexpected exception occurred while getting dataset dataprep_clean_dataset_review from the repository.
Exception occurred while reading a Parquet file from workspace/test/datasets/fal/dataprep/dataprep_clean_dataset_review.parquet.
An error occurred while calling the read_parquet method registered to the pandas backend.
Original Message: pyarrow>=15.0.0 is required to use the pyarrow filesystem.
Original exception: An error occurred while calling the read_parquet method registered to the pandas backend.
Original Message: pyarrow>=15.0.0 is required to use the pyarrow filesystem.
[01/31/2025 08:01:02 AM] [DEBUG] [genailab.infra.persist.repo.object.rao.RAO] [rao] [__init__] : RAO created at workspace/test/datasets/ral/
[01/31/2025 08:01:02 AM] [DEBUG] [genailab.infra.persist.repo.object.dao.DAO] [dao] [__init__] : DAO created at workspace/test/datasets/dal/
[01/31/2025 08:01:03 AM] [DEBUG] [genailab.flow.base.stage.TQAStage] [stage] [run] : Inside TQAStage: run
[01/31/2025 08:01:03 AM] [DEBUG] [genailab.flow.base.stage.TQAStage] [stage] [_dataset_exists] : Inside TQAStage: _dataset_exists
[01/31/2025 08:01:03 AM] [DEBUG] [genailab.flow.base.stage.TQAStage] [stage] [_fresh_cache_exists] : Inside TQAStage: _fresh_cache_exists
[01/31/2025 08:01:03 AM] [DEBUG] [genailab.flow.base.stage.TQAStage] [stage] [_get_dataset] : Inside TQAStage: _get_dataset
[01/31/2025 08:01:03 AM] [DEBUG] [genailab.flow.base.stage.TQAStage] [stage] [_dataset_exists] : Inside TQAStage: _dataset_exists
[01/31/2025 08:01:03 AM] [DEBUG] [genailab.flow.base.stage.TQAStage] [stage] [_fresh_cache_exists] : The target dataset cache for Feature Engineering Phase/Text Quality Analysis Stage does not exist in the repository.
[01/31/2025 08:01:03 AM] [DEBUG] [genailab.flow.base.stage.TQAStage] [stage] [_run] : Inside TQAStage: _run
[01/31/2025 08:01:03 AM] [DEBUG] [genailab.flow.base.stage.TQAStage] [stage] [_remove_dataset] : Inside TQAStage: _remove_dataset
[01/31/2025 08:01:03 AM] [DEBUG] [genailab.flow.base.stage.TQAStage] [stage] [_get_dataset] : Inside TQAStage: _get_dataset
[01/31/2025 08:01:03 AM] [DEBUG] [root] [factory] [get_reader] : Requesting a dask_parquet reader from the DataFrameIOFactory
[01/31/2025 08:01:03 AM] [ERROR] [genailab.flow.base.stage.TQAStage] [stage] [_get_dataset] : Unexpected exception occurred while getting dataset dataprep_clean_dataset_review from the repository.
Exception occurred while reading a Parquet file from workspace/test/datasets/fal/dataprep/dataprep_clean_dataset_review.parquet.
An error occurred while calling the read_parquet method registered to the pandas backend.
Original Message: URI has empty scheme: 'workspace/test/datasets/fal/dataprep/dataprep_clean_dataset_review.parquet'
Original exception: An error occurred while calling the read_parquet method registered to the pandas backend.
Original Message: URI has empty scheme: 'workspace/test/datasets/fal/dataprep/dataprep_clean_dataset_review.parquet'
Traceback (most recent call last):
  File "/home/john/miniconda3/envs/genai/lib/python3.8/site-packages/dask/backends.py", line 135, in wrapper
    return func(*args, **kwargs)
  File "/home/john/miniconda3/envs/genai/lib/python3.8/site-packages/dask/dataframe/io/parquet/core.py", line 519, in read_parquet
    fs, paths, dataset_options, open_file_options = engine.extract_filesystem(
  File "/home/john/miniconda3/envs/genai/lib/python3.8/site-packages/dask/dataframe/io/parquet/arrow.py", line 457, in extract_filesystem
    fs = type(pa_fs.FileSystem.from_uri(urlpath[0])[0])(
  File "pyarrow/_fs.pyx", line 471, in pyarrow._fs.FileSystem.from_uri
  File "pyarrow/error.pxi", line 154, in pyarrow.lib.pyarrow_internal_check_status
  File "pyarrow/error.pxi", line 91, in pyarrow.lib.check_status
pyarrow.lib.ArrowInvalid: URI has empty scheme: 'workspace/test/datasets/fal/dataprep/dataprep_clean_dataset_review.parquet'

The above exception was the direct cause of the following exception:

Traceback (most recent call last):
  File "/home/john/projects/genailab/genailab/infra/persist/repo/file/dask.py", line 57, in read
    df = dd.read_parquet(path=filepath, **self._kwargs)
  File "/home/john/miniconda3/envs/genai/lib/python3.8/site-packages/dask/backends.py", line 137, in wrapper
    raise type(e)(
pyarrow.lib.ArrowInvalid: An error occurred while calling the read_parquet method registered to the pandas backend.
Original Message: URI has empty scheme: 'workspace/test/datasets/fal/dataprep/dataprep_clean_dataset_review.parquet'

The above exception was the direct cause of the following exception:

Traceback (most recent call last):
  File "/home/john/projects/genailab/genailab/flow/base/stage.py", line 255, in _get_dataset
    dataset = self._repo.get(
  File "/home/john/projects/genailab/genailab/infra/persist/repo/dataset.py", line 165, in get
    df = self._fao.read(filepath=dataset.file.path, dftype=dftype, spark=spark)
  File "/home/john/projects/genailab/genailab/infra/persist/repo/file/fao.py", line 130, in read
    return reader.read(filepath=filepath, spark=spark)
  File "/home/john/projects/genailab/genailab/infra/persist/repo/file/dask.py", line 68, in read
    raise FileIOException(msg, e) from e
genailab.infra.exception.file.FileIOException: Exception occurred while reading a Parquet file from workspace/test/datasets/fal/dataprep/dataprep_clean_dataset_review.parquet.
An error occurred while calling the read_parquet method registered to the pandas backend.
Original Message: URI has empty scheme: 'workspace/test/datasets/fal/dataprep/dataprep_clean_dataset_review.parquet'
Original exception: An error occurred while calling the read_parquet method registered to the pandas backend.
Original Message: URI has empty scheme: 'workspace/test/datasets/fal/dataprep/dataprep_clean_dataset_review.parquet'
[01/31/2025 08:01:03 AM] [ERROR] [Stage.run] [stage] [wrapper] : Exception occurred in Stage.run called with force=True
Unexpected exception occurred while getting dataset dataprep_clean_dataset_review from the repository.
Exception occurred while reading a Parquet file from workspace/test/datasets/fal/dataprep/dataprep_clean_dataset_review.parquet.
An error occurred while calling the read_parquet method registered to the pandas backend.
Original Message: URI has empty scheme: 'workspace/test/datasets/fal/dataprep/dataprep_clean_dataset_review.parquet'
Original exception: An error occurred while calling the read_parquet method registered to the pandas backend.
Original Message: URI has empty scheme: 'workspace/test/datasets/fal/dataprep/dataprep_clean_dataset_review.parquet'
Traceback (most recent call last):
  File "/home/john/miniconda3/envs/genai/lib/python3.8/site-packages/dask/backends.py", line 135, in wrapper
    return func(*args, **kwargs)
  File "/home/john/miniconda3/envs/genai/lib/python3.8/site-packages/dask/dataframe/io/parquet/core.py", line 519, in read_parquet
    fs, paths, dataset_options, open_file_options = engine.extract_filesystem(
  File "/home/john/miniconda3/envs/genai/lib/python3.8/site-packages/dask/dataframe/io/parquet/arrow.py", line 457, in extract_filesystem
    fs = type(pa_fs.FileSystem.from_uri(urlpath[0])[0])(
  File "pyarrow/_fs.pyx", line 471, in pyarrow._fs.FileSystem.from_uri
  File "pyarrow/error.pxi", line 154, in pyarrow.lib.pyarrow_internal_check_status
  File "pyarrow/error.pxi", line 91, in pyarrow.lib.check_status
pyarrow.lib.ArrowInvalid: URI has empty scheme: 'workspace/test/datasets/fal/dataprep/dataprep_clean_dataset_review.parquet'

The above exception was the direct cause of the following exception:

Traceback (most recent call last):
  File "/home/john/projects/genailab/genailab/infra/persist/repo/file/dask.py", line 57, in read
    df = dd.read_parquet(path=filepath, **self._kwargs)
  File "/home/john/miniconda3/envs/genai/lib/python3.8/site-packages/dask/backends.py", line 137, in wrapper
    raise type(e)(
pyarrow.lib.ArrowInvalid: An error occurred while calling the read_parquet method registered to the pandas backend.
Original Message: URI has empty scheme: 'workspace/test/datasets/fal/dataprep/dataprep_clean_dataset_review.parquet'

The above exception was the direct cause of the following exception:

Traceback (most recent call last):
  File "/home/john/projects/genailab/genailab/flow/base/stage.py", line 255, in _get_dataset
    dataset = self._repo.get(
  File "/home/john/projects/genailab/genailab/infra/persist/repo/dataset.py", line 165, in get
    df = self._fao.read(filepath=dataset.file.path, dftype=dftype, spark=spark)
  File "/home/john/projects/genailab/genailab/infra/persist/repo/file/fao.py", line 130, in read
    return reader.read(filepath=filepath, spark=spark)
  File "/home/john/projects/genailab/genailab/infra/persist/repo/file/dask.py", line 68, in read
    raise FileIOException(msg, e) from e
genailab.infra.exception.file.FileIOException: Exception occurred while reading a Parquet file from workspace/test/datasets/fal/dataprep/dataprep_clean_dataset_review.parquet.
An error occurred while calling the read_parquet method registered to the pandas backend.
Original Message: URI has empty scheme: 'workspace/test/datasets/fal/dataprep/dataprep_clean_dataset_review.parquet'
Original exception: An error occurred while calling the read_parquet method registered to the pandas backend.
Original Message: URI has empty scheme: 'workspace/test/datasets/fal/dataprep/dataprep_clean_dataset_review.parquet'

During handling of the above exception, another exception occurred:

Traceback (most recent call last):
  File "/home/john/projects/genailab/genailab/infra/service/logging/stage.py", line 58, in wrapper
    result = func(self, *args, **kwargs)
  File "/home/john/projects/genailab/genailab/flow/base/stage.py", line 147, in run
    return self._run()
  File "/home/john/projects/genailab/genailab/flow/feature/tqa/stage.py", line 86, in _run
    source = self._get_dataset(config=self._source_config)
  File "/home/john/projects/genailab/genailab/flow/base/stage.py", line 271, in _get_dataset
    raise Exception(msg)
Exception: Unexpected exception occurred while getting dataset dataprep_clean_dataset_review from the repository.
Exception occurred while reading a Parquet file from workspace/test/datasets/fal/dataprep/dataprep_clean_dataset_review.parquet.
An error occurred while calling the read_parquet method registered to the pandas backend.
Original Message: URI has empty scheme: 'workspace/test/datasets/fal/dataprep/dataprep_clean_dataset_review.parquet'
Original exception: An error occurred while calling the read_parquet method registered to the pandas backend.
Original Message: URI has empty scheme: 'workspace/test/datasets/fal/dataprep/dataprep_clean_dataset_review.parquet'
[01/31/2025 03:08:37 PM] [DEBUG] [genailab.infra.persist.repo.object.rao.RAO] [rao] [__init__] : RAO created at workspace/test/datasets/ral/
[01/31/2025 03:08:37 PM] [DEBUG] [genailab.infra.persist.repo.object.dao.DAO] [dao] [__init__] : DAO created at workspace/test/datasets/dal/
[01/31/2025 03:08:38 PM] [DEBUG] [genailab.flow.base.stage.TQAStage] [stage] [run] : Inside TQAStage: run
[01/31/2025 03:08:38 PM] [DEBUG] [genailab.flow.base.stage.TQAStage] [stage] [_dataset_exists] : Inside TQAStage: _dataset_exists
[01/31/2025 03:08:38 PM] [DEBUG] [genailab.flow.base.stage.TQAStage] [stage] [_fresh_cache_exists] : Inside TQAStage: _fresh_cache_exists
[01/31/2025 03:08:38 PM] [DEBUG] [genailab.flow.base.stage.TQAStage] [stage] [_get_dataset] : Inside TQAStage: _get_dataset
[01/31/2025 03:08:38 PM] [DEBUG] [genailab.flow.base.stage.TQAStage] [stage] [_dataset_exists] : Inside TQAStage: _dataset_exists
[01/31/2025 03:08:38 PM] [DEBUG] [genailab.flow.base.stage.TQAStage] [stage] [_fresh_cache_exists] : The target dataset cache for Feature Engineering Phase/Text Quality Analysis Stage does not exist in the repository.
[01/31/2025 03:08:38 PM] [DEBUG] [genailab.flow.base.stage.TQAStage] [stage] [_run] : Inside TQAStage: _run
[01/31/2025 03:08:38 PM] [DEBUG] [genailab.flow.base.stage.TQAStage] [stage] [_remove_dataset] : Inside TQAStage: _remove_dataset
[01/31/2025 03:08:38 PM] [DEBUG] [genailab.flow.base.stage.TQAStage] [stage] [_get_dataset] : Inside TQAStage: _get_dataset
[01/31/2025 03:08:38 PM] [DEBUG] [root] [factory] [get_reader] : Requesting a pandas_parquet reader from the DataFrameIOFactory
[01/31/2025 03:08:39 PM] [DEBUG] [genailab.infra.persist.repo.file.pandas.PandasDataFrameParquetReader] [pandas] [read] : PandasDataFrameParquetReader read from workspace/test/datasets/fal/dataprep/dataprep_clean_dataset_review.parquet
[01/31/2025 03:08:39 PM] [DEBUG] [genailab.asset.dataset.state.DatasetState] [state] [add_event] : Added {'timestamp': datetime.datetime(2025, 1, 31, 15, 8, 39, 7263), 'entity': 'TQAStage', 'event': 'Accessed by TQAStage'} to the event log at 2025-01-31 15:08:39.007265.
[01/31/2025 03:08:39 PM] [DEBUG] [genailab.asset.dataset.state.DatasetState] [state] [access] : Dataset accessed by TQAStage at 2025-01-31 15:08:39.007254
[01/31/2025 03:08:39 PM] [DEBUG] [genailab.flow.base.stage.TQAStage] [stage] [_validate_dataframe_type] : Inside TQAStage: _validate_dataframe_type
[01/31/2025 03:08:39 PM] [DEBUG] [asyncio] [selector_events] [__init__] : Using selector: EpollSelector
[01/31/2025 03:08:40 PM] [ERROR] [genailab.flow.base.stage.TQAStage] [stage] [_run] : Error in task TQATask: [E050] Can't find model 'en_core_web_sm'. It doesn't seem to be a Python package or a valid path to a data directory.
[01/31/2025 03:08:40 PM] [ERROR] [Stage.run] [stage] [wrapper] : Exception occurred in Stage.run called with force=True
Error in task TQATask: [E050] Can't find model 'en_core_web_sm'. It doesn't seem to be a Python package or a valid path to a data directory.
Traceback (most recent call last):
  File "/home/john/projects/genailab/genailab/flow/feature/tqa/stage.py", line 94, in _run
    dataframe = task.run(dataframe)
  File "/home/john/projects/genailab/genailab/flow/feature/tqa/task.py", line 146, in run
    return self._analyst.analyze(data=data)
  File "/home/john/projects/genailab/genailab/flow/feature/tqa/task.py", line 335, in analyze
    nlp = spacy.load("en_core_web_sm")
  File "/home/john/miniconda3/envs/genai/lib/python3.8/site-packages/spacy/__init__.py", line 51, in load
    return util.load_model(
  File "/home/john/miniconda3/envs/genai/lib/python3.8/site-packages/spacy/util.py", line 472, in load_model
    raise IOError(Errors.E050.format(name=name))
OSError: [E050] Can't find model 'en_core_web_sm'. It doesn't seem to be a Python package or a valid path to a data directory.

During handling of the above exception, another exception occurred:

Traceback (most recent call last):
  File "/home/john/projects/genailab/genailab/infra/service/logging/stage.py", line 58, in wrapper
    result = func(self, *args, **kwargs)
  File "/home/john/projects/genailab/genailab/flow/base/stage.py", line 147, in run
    return self._run()
  File "/home/john/projects/genailab/genailab/flow/feature/tqa/stage.py", line 97, in _run
    raise RuntimeError(f"Error in task {task.__class__.__name__}: {e}")
RuntimeError: Error in task TQATask: [E050] Can't find model 'en_core_web_sm'. It doesn't seem to be a Python package or a valid path to a data directory.
[01/31/2025 03:12:55 PM] [DEBUG] [genailab.infra.persist.repo.object.rao.RAO] [rao] [__init__] : RAO created at workspace/test/datasets/ral/
[01/31/2025 03:12:55 PM] [DEBUG] [genailab.infra.persist.repo.object.dao.DAO] [dao] [__init__] : DAO created at workspace/test/datasets/dal/
[01/31/2025 03:12:56 PM] [DEBUG] [genailab.flow.base.stage.TQAStage] [stage] [run] : Inside TQAStage: run
[01/31/2025 03:12:56 PM] [DEBUG] [genailab.flow.base.stage.TQAStage] [stage] [_dataset_exists] : Inside TQAStage: _dataset_exists
[01/31/2025 03:12:56 PM] [DEBUG] [genailab.flow.base.stage.TQAStage] [stage] [_fresh_cache_exists] : Inside TQAStage: _fresh_cache_exists
[01/31/2025 03:12:56 PM] [DEBUG] [genailab.flow.base.stage.TQAStage] [stage] [_get_dataset] : Inside TQAStage: _get_dataset
[01/31/2025 03:12:56 PM] [DEBUG] [genailab.flow.base.stage.TQAStage] [stage] [_dataset_exists] : Inside TQAStage: _dataset_exists
[01/31/2025 03:12:56 PM] [DEBUG] [genailab.flow.base.stage.TQAStage] [stage] [_fresh_cache_exists] : The target dataset cache for Feature Engineering Phase/Text Quality Analysis Stage does not exist in the repository.
[01/31/2025 03:12:56 PM] [DEBUG] [genailab.flow.base.stage.TQAStage] [stage] [_run] : Inside TQAStage: _run
[01/31/2025 03:12:56 PM] [DEBUG] [genailab.flow.base.stage.TQAStage] [stage] [_remove_dataset] : Inside TQAStage: _remove_dataset
[01/31/2025 03:12:56 PM] [DEBUG] [genailab.flow.base.stage.TQAStage] [stage] [_get_dataset] : Inside TQAStage: _get_dataset
[01/31/2025 03:12:56 PM] [DEBUG] [root] [factory] [get_reader] : Requesting a pandas_parquet reader from the DataFrameIOFactory
[01/31/2025 03:12:56 PM] [DEBUG] [genailab.infra.persist.repo.file.pandas.PandasDataFrameParquetReader] [pandas] [read] : PandasDataFrameParquetReader read from workspace/test/datasets/fal/dataprep/dataprep_clean_dataset_review.parquet
[01/31/2025 03:12:56 PM] [DEBUG] [genailab.asset.dataset.state.DatasetState] [state] [add_event] : Added {'timestamp': datetime.datetime(2025, 1, 31, 15, 12, 56, 670857), 'entity': 'TQAStage', 'event': 'Accessed by TQAStage'} to the event log at 2025-01-31 15:12:56.670860.
[01/31/2025 03:12:56 PM] [DEBUG] [genailab.asset.dataset.state.DatasetState] [state] [access] : Dataset accessed by TQAStage at 2025-01-31 15:12:56.670848
[01/31/2025 03:12:56 PM] [DEBUG] [genailab.flow.base.stage.TQAStage] [stage] [_validate_dataframe_type] : Inside TQAStage: _validate_dataframe_type
[01/31/2025 03:12:56 PM] [DEBUG] [asyncio] [selector_events] [__init__] : Using selector: EpollSelector
[01/31/2025 03:12:59 PM] [ERROR] [genailab.flow.base.stage.TQAStage] [stage] [_run] : Error in task TQATask: Expected iterable of tuples of (name, dtype), got (Empty DataFrame
Columns: [id, app_id, app_name, category_id, author, rating, content, vote_sum, vote_count, date, category, noun_count, verb_count, adjective_count, adverb_count, aspect_verb_pairs, noun_phrases, verb_phrases, adverbial_phrases, review_length, lexical_density, dependency_depth, tqa_score]
Index: []

[0 rows x 23 columns],)
[01/31/2025 03:12:59 PM] [ERROR] [Stage.run] [stage] [wrapper] : Exception occurred in Stage.run called with force=True
Error in task TQATask: Expected iterable of tuples of (name, dtype), got (Empty DataFrame
Columns: [id, app_id, app_name, category_id, author, rating, content, vote_sum, vote_count, date, category, noun_count, verb_count, adjective_count, adverb_count, aspect_verb_pairs, noun_phrases, verb_phrases, adverbial_phrases, review_length, lexical_density, dependency_depth, tqa_score]
Index: []

[0 rows x 23 columns],)
Traceback (most recent call last):
  File "/home/john/miniconda3/envs/genai/lib/python3.8/site-packages/dask/dataframe/dispatch.py", line 130, in make_meta
    return make_meta_dispatch(x, index=index)
  File "/home/john/miniconda3/envs/genai/lib/python3.8/site-packages/dask/utils.py", line 641, in __call__
    meth = self.dispatch(type(arg))
  File "/home/john/miniconda3/envs/genai/lib/python3.8/site-packages/dask/utils.py", line 635, in dispatch
    raise TypeError(f"No dispatch for {cls}")
TypeError: No dispatch for <class 'tuple'>

During handling of the above exception, another exception occurred:

Traceback (most recent call last):
  File "/home/john/projects/genailab/genailab/flow/feature/tqa/stage.py", line 94, in _run
    dataframe = task.run(dataframe)
  File "/home/john/projects/genailab/genailab/flow/feature/tqa/task.py", line 146, in run
    return self._analyst.analyze(data=data)
  File "/home/john/projects/genailab/genailab/flow/feature/tqa/task.py", line 353, in analyze
    results = ddf.apply(lambda row: self._process_row(row, function_words, nlp),
  File "/home/john/miniconda3/envs/genai/lib/python3.8/site-packages/dask/dataframe/core.py", line 5919, in apply
    return map_partitions(M.apply, self, func, args=args, meta=meta, **kwds)
  File "/home/john/miniconda3/envs/genai/lib/python3.8/site-packages/dask/dataframe/core.py", line 6880, in map_partitions
    meta = _get_meta_map_partitions(args, dfs, func, kwargs, meta, parent_meta)
  File "/home/john/miniconda3/envs/genai/lib/python3.8/site-packages/dask/dataframe/core.py", line 6994, in _get_meta_map_partitions
    meta = make_meta(meta, index=meta_index, parent_meta=parent_meta)
  File "/home/john/miniconda3/envs/genai/lib/python3.8/site-packages/dask/dataframe/dispatch.py", line 134, in make_meta
    return func(x, index=index)
  File "/home/john/miniconda3/envs/genai/lib/python3.8/site-packages/dask/dataframe/backends.py", line 265, in make_meta_object
    raise ValueError(f"Expected iterable of tuples of (name, dtype), got {x}")
ValueError: Expected iterable of tuples of (name, dtype), got (Empty DataFrame
Columns: [id, app_id, app_name, category_id, author, rating, content, vote_sum, vote_count, date, category, noun_count, verb_count, adjective_count, adverb_count, aspect_verb_pairs, noun_phrases, verb_phrases, adverbial_phrases, review_length, lexical_density, dependency_depth, tqa_score]
Index: []

[0 rows x 23 columns],)

During handling of the above exception, another exception occurred:

Traceback (most recent call last):
  File "/home/john/projects/genailab/genailab/infra/service/logging/stage.py", line 58, in wrapper
    result = func(self, *args, **kwargs)
  File "/home/john/projects/genailab/genailab/flow/base/stage.py", line 147, in run
    return self._run()
  File "/home/john/projects/genailab/genailab/flow/feature/tqa/stage.py", line 97, in _run
    raise RuntimeError(f"Error in task {task.__class__.__name__}: {e}")
RuntimeError: Error in task TQATask: Expected iterable of tuples of (name, dtype), got (Empty DataFrame
Columns: [id, app_id, app_name, category_id, author, rating, content, vote_sum, vote_count, date, category, noun_count, verb_count, adjective_count, adverb_count, aspect_verb_pairs, noun_phrases, verb_phrases, adverbial_phrases, review_length, lexical_density, dependency_depth, tqa_score]
Index: []

[0 rows x 23 columns],)
